Workbook

Sheet Dashboard
A2: ANCL LOGISTICS · ANNUAL DASHBOARD · FY 2026–27 (Apr 2026 – Mar 2027)
A3: All values auto-populate from monthly sheets. No manual entry needed on this sheet.
A4: 🟩 Green = Income 🟥 Red = Expenses 🟦 Blue = Auto-calculated Profit = Income − Expenses
A5: Month | B5: Revenue (To Pay) ₹ | C5: Received ₹ | D5: Return/Adj ₹ | E5: Total Income ₹ | F5: Trip Expenses ₹ | G5: Overhead Exp ₹ | H5: Total Expenses ₹ | I5: Own Profit ₹ | J5: Rented Profit ₹ | K5: Net Profit ₹ | L5: Profit % | M5: Pending Freight ₹ | N5: Trips
A6: Apr 2026 | B6: =IFERROR('Apr 26'!G116,0) -> 18980 | C6: =IFERROR('Apr 26'!H116,0) -> 17825 | D6: =IFERROR('Apr 26'!J116,0) -> 0 | E6: =IFERROR('Apr 26'!H130,0) -> 36805 | F6: =IFERROR('Apr 26'!K116+'Apr 26'!L116+'Apr 26'!M116+'Apr 26'!N116+'Apr 26'!O116+'Apr 26'!P116+'Apr 26'!Q116+'Apr 26'!R116+'Apr 26'!S116+'Apr 26'!T116+'Apr 26'!U116,0) -> 9550 | G6: =IFERROR('Apr 26'!AB116,0) -> 0 | H6: =IFERROR('Apr 26'!H171,0) -> 9550 | I6: =IFERROR(SUMIF('Apr 26'!F5:'Apr 26'!F115,"Own",'Apr 26'!X5:'Apr 26'!X115),0) -> 24895 | J6: =IFERROR(SUMIF('Apr 26'!F5:'Apr 26'!F115,"Rented",'Apr 26'!X5:'Apr 26'!X115),0) -> 1800 | K6: =IFERROR('Apr 26'!H173,0) -> 27255 | L6: =IFERROR(K6/E6,0) -> 0.74052439 | M6: =IFERROR(SUM('Apr 26'!I5:'Apr 26'!I115),0) -> 150 | N6: =IFERROR(COUNTA('Apr 26'!C5:'Apr 26'!C115),0) -> 5
A7: May 2026 | B7: =IFERROR('May 26'!G116,0) -> 0 | C7: =IFERROR('May 26'!H116,0) -> 0 | D7: =IFERROR('May 26'!J116,0) -> 0 | E7: =IFERROR('May 26'!H130,0) -> 0 | F7: =IFERROR('May 26'!K116+'May 26'!L116+'May 26'!M116+'May 26'!N116+'May 26'!O116+'May 26'!P116+'May 26'!Q116+'May 26'!R116+'May 26'!S116+'May 26'!T116+'May 26'!U116,0) -> 0 | G7: =IFERROR('May 26'!AB116,0) -> 0 | H7: =IFERROR('May 26'!H171,0) -> 0 | I7: =IFERROR(SUMIF('May 26'!F5:'May 26'!F115,"Own",'May 26'!X5:'May 26'!X115),0) -> 0 | J7: =IFERROR(SUMIF('May 26'!F5:'May 26'!F115,"Rented",'May 26'!X5:'May 26'!X115),0) -> 0 | K7: =IFERROR('May 26'!H173,0) -> 0 | L7: =IFERROR(K7/E7,0) -> 0 | M7: =IFERROR(SUM('May 26'!I5:'May 26'!I115),0) -> 0 | N7: =IFERROR(COUNTA('May 26'!C5:'May 26'!C115),0) -> 0
A8: Jun 2026 | B8: =IFERROR('Jun 26'!G116,0) -> 0 | C8: =IFERROR('Jun 26'!H116,0) -> 0 | D8: =IFERROR('Jun 26'!J116,0) -> 0 | E8: =IFERROR('Jun 26'!H130,0) -> 0 | F8: =IFERROR('Jun 26'!K116+'Jun 26'!L116+'Jun 26'!M116+'Jun 26'!N116+'Jun 26'!O116+'Jun 26'!P116+'Jun 26'!Q116+'Jun 26'!R116+'Jun 26'!S116+'Jun 26'!T116+'Jun 26'!U116,0) -> 0 | G8: =IFERROR('Jun 26'!AB116,0) -> 0 | H8: =IFERROR('Jun 26'!H171,0) -> 0 | I8: =IFERROR(SUMIF('Jun 26'!F5:'Jun 26'!F115,"Own",'Jun 26'!X5:'Jun 26'!X115),0) -> 0 | J8: =IFERROR(SUMIF('Jun 26'!F5:'Jun 26'!F115,"Rented",'Jun 26'!X5:'Jun 26'!X115),0) -> 0 | K8: =IFERROR('Jun 26'!H173,0) -> 0 | L8: =IFERROR(K8/E8,0) -> 0 | M8: =IFERROR(SUM('Jun 26'!I5:'Jun 26'!I115),0) -> 0 | N8: =IFERROR(COUNTA('Jun 26'!C5:'Jun 26'!C115),0) -> 0
A9: Jul 2026 | B9: =IFERROR('Jul 26'!G116,0) -> 0 | C9: =IFERROR('Jul 26'!H116,0) -> 0 | D9: =IFERROR('Jul 26'!J116,0) -> 0 | E9: =IFERROR('Jul 26'!H130,0) -> 0 | F9: =IFERROR('Jul 26'!K116+'Jul 26'!L116+'Jul 26'!M116+'Jul 26'!N116+'Jul 26'!O116+'Jul 26'!P116+'Jul 26'!Q116+'Jul 26'!R116+'Jul 26'!S116+'Jul 26'!T116+'Jul 26'!U116,0) -> 0 | G9: =IFERROR('Jul 26'!AB116,0) -> 0 | H9: =IFERROR('Jul 26'!H171,0) -> 0 | I9: =IFERROR(SUMIF('Jul 26'!F5:'Jul 26'!F115,"Own",'Jul 26'!X5:'Jul 26'!X115),0) -> 0 | J9: =IFERROR(SUMIF('Jul 26'!F5:'Jul 26'!F115,"Rented",'Jul 26'!X5:'Jul 26'!X115),0) -> 0 | K9: =IFERROR('Jul 26'!H173,0) -> 0 | L9: =IFERROR(K9/E9,0) -> 0 | M9: =IFERROR(SUM('Jul 26'!I5:'Jul 26'!I115),0) -> 0 | N9: =IFERROR(COUNTA('Jul 26'!C5:'Jul 26'!C115),0) -> 0
A10: Aug 2026 | B10: =IFERROR('Aug 26'!G116,0) -> 0 | C10: =IFERROR('Aug 26'!H116,0) -> 0 | D10: =IFERROR('Aug 26'!J116,0) -> 0 | E10: =IFERROR('Aug 26'!H130,0) -> 0 | F10: =IFERROR('Aug 26'!K116+'Aug 26'!L116+'Aug 26'!M116+'Aug 26'!N116+'Aug 26'!O116+'Aug 26'!P116+'Aug 26'!Q116+'Aug 26'!R116+'Aug 26'!S116+'Aug 26'!T116+'Aug 26'!U116,0) -> 0 | G10: =IFERROR('Aug 26'!AB116,0) -> 0 | H10: =IFERROR('Aug 26'!H171,0) -> 0 | I10: =IFERROR(SUMIF('Aug 26'!F5:'Aug 26'!F115,"Own",'Aug 26'!X5:'Aug 26'!X115),0) -> 0 | J10: =IFERROR(SUMIF('Aug 26'!F5:'Aug 26'!F115,"Rented",'Aug 26'!X5:'Aug 26'!X115),0) -> 0 | K10: =IFERROR('Aug 26'!H173,0) -> 0 | L10: =IFERROR(K10/E10,0) -> 0 | M10: =IFERROR(SUM('Aug 26'!I5:'Aug 26'!I115),0) -> 0 | N10: =IFERROR(COUNTA('Aug 26'!C5:'Aug 26'!C115),0) -> 0
A11: Sep 2026 | B11: =IFERROR('Sep 26'!G116,0) -> 0 | C11: =IFERROR('Sep 26'!H116,0) -> 0 | D11: =IFERROR('Sep 26'!J116,0) -> 0 | E11: =IFERROR('Sep 26'!H130,0) -> 0 | F11: =IFERROR('Sep 26'!K116+'Sep 26'!L116+'Sep 26'!M116+'Sep 26'!N116+'Sep 26'!O116+'Sep 26'!P116+'Sep 26'!Q116+'Sep 26'!R116+'Sep 26'!S116+'Sep 26'!T116+'Sep 26'!U116,0) -> 0 | G11: =IFERROR('Sep 26'!AB116,0) -> 0 | H11: =IFERROR('Sep 26'!H171,0) -> 0 | I11: =IFERROR(SUMIF('Sep 26'!F5:'Sep 26'!F115,"Own",'Sep 26'!X5:'Sep 26'!X115),0) -> 0 | J11: =IFERROR(SUMIF('Sep 26'!F5:'Sep 26'!F115,"Rented",'Sep 26'!X5:'Sep 26'!X115),0) -> 0 | K11: =IFERROR('Sep 26'!H173,0) -> 0 | L11: =IFERROR(K11/E11,0) -> 0 | M11: =IFERROR(SUM('Sep 26'!I5:'Sep 26'!I115),0) -> 0 | N11: =IFERROR(COUNTA('Sep 26'!C5:'Sep 26'!C115),0) -> 0
A12: Oct 2026 | B12: =IFERROR('Oct 26'!G116,0) -> 0 | C12: =IFERROR('Oct 26'!H116,0) -> 0 | D12: =IFERROR('Oct 26'!J116,0) -> 0 | E12: =IFERROR('Oct 26'!H130,0) -> 0 | F12: =IFERROR('Oct 26'!K116+'Oct 26'!L116+'Oct 26'!M116+'Oct 26'!N116+'Oct 26'!O116+'Oct 26'!P116+'Oct 26'!Q116+'Oct 26'!R116+'Oct 26'!S116+'Oct 26'!T116+'Oct 26'!U116,0) -> 0 | G12: =IFERROR('Oct 26'!AB116,0) -> 0 | H12: =IFERROR('Oct 26'!H171,0) -> 0 | I12: =IFERROR(SUMIF('Oct 26'!F5:'Oct 26'!F115,"Own",'Oct 26'!X5:'Oct 26'!X115),0) -> 0 | J12: =IFERROR(SUMIF('Oct 26'!F5:'Oct 26'!F115,"Rented",'Oct 26'!X5:'Oct 26'!X115),0) -> 0 | K12: =IFERROR('Oct 26'!H173,0) -> 0 | L12: =IFERROR(K12/E12,0) -> 0 | M12: =IFERROR(SUM('Oct 26'!I5:'Oct 26'!I115),0) -> 0 | N12: =IFERROR(COUNTA('Oct 26'!C5:'Oct 26'!C115),0) -> 0
A13: Nov 2026 | B13: =IFERROR('Nov 26'!G116,0) -> 0 | C13: =IFERROR('Nov 26'!H116,0) -> 0 | D13: =IFERROR('Nov 26'!J116,0) -> 0 | E13: =IFERROR('Nov 26'!H130,0) -> 0 | F13: =IFERROR('Nov 26'!K116+'Nov 26'!L116+'Nov 26'!M116+'Nov 26'!N116+'Nov 26'!O116+'Nov 26'!P116+'Nov 26'!Q116+'Nov 26'!R116+'Nov 26'!S116+'Nov 26'!T116+'Nov 26'!U116,0) -> 0 | G13: =IFERROR('Nov 26'!AB116,0) -> 0 | H13: =IFERROR('Nov 26'!H171,0) -> 0 | I13: =IFERROR(SUMIF('Nov 26'!F5:'Nov 26'!F115,"Own",'Nov 26'!X5:'Nov 26'!X115),0) -> 0 | J13: =IFERROR(SUMIF('Nov 26'!F5:'Nov 26'!F115,"Rented",'Nov 26'!X5:'Nov 26'!X115),0) -> 0 | K13: =IFERROR('Nov 26'!H173,0) -> 0 | L13: =IFERROR(K13/E13,0) -> 0 | M13: =IFERROR(SUM('Nov 26'!I5:'Nov 26'!I115),0) -> 0 | N13: =IFERROR(COUNTA('Nov 26'!C5:'Nov 26'!C115),0) -> 0
A14: Dec 2026 | B14: =IFERROR('Dec 26'!G116,0) -> 0 | C14: =IFERROR('Dec 26'!H116,0) -> 0 | D14: =IFERROR('Dec 26'!J116,0) -> 0 | E14: =IFERROR('Dec 26'!H130,0) -> 0 | F14: =IFERROR('Dec 26'!K116+'Dec 26'!L116+'Dec 26'!M116+'Dec 26'!N116+'Dec 26'!O116+'Dec 26'!P116+'Dec 26'!Q116+'Dec 26'!R116+'Dec 26'!S116+'Dec 26'!T116+'Dec 26'!U116,0) -> 0 | G14: =IFERROR('Dec 26'!AB116,0) -> 0 | H14: =IFERROR('Dec 26'!H171,0) -> 0 | I14: =IFERROR(SUMIF('Dec 26'!F5:'Dec 26'!F115,"Own",'Dec 26'!X5:'Dec 26'!X115),0) -> 0 | J14: =IFERROR(SUMIF('Dec 26'!F5:'Dec 26'!F115,"Rented",'Dec 26'!X5:'Dec 26'!X115),0) -> 0 | K14: =IFERROR('Dec 26'!H173,0) -> 0 | L14: =IFERROR(K14/E14,0) -> 0 | M14: =IFERROR(SUM('Dec 26'!I5:'Dec 26'!I115),0) -> 0 | N14: =IFERROR(COUNTA('Dec 26'!C5:'Dec 26'!C115),0) -> 0
A15: Jan 2027 | B15: =IFERROR('Jan 27'!G116,0) -> 0 | C15: =IFERROR('Jan 27'!H116,0) -> 0 | D15: =IFERROR('Jan 27'!J116,0) -> 0 | E15: =IFERROR('Jan 27'!H130,0) -> 0 | F15: =IFERROR('Jan 27'!K116+'Jan 27'!L116+'Jan 27'!M116+'Jan 27'!N116+'Jan 27'!O116+'Jan 27'!P116+'Jan 27'!Q116+'Jan 27'!R116+'Jan 27'!S116+'Jan 27'!T116+'Jan 27'!U116,0) -> 0 | G15: =IFERROR('Jan 27'!AB116,0) -> 0 | H15: =IFERROR('Jan 27'!H171,0) -> 0 | I15: =IFERROR(SUMIF('Jan 27'!F5:'Jan 27'!F115,"Own",'Jan 27'!X5:'Jan 27'!X115),0) -> 0 | J15: =IFERROR(SUMIF('Jan 27'!F5:'Jan 27'!F115,"Rented",'Jan 27'!X5:'Jan 27'!X115),0) -> 0 | K15: =IFERROR('Jan 27'!H173,0) -> 0 | L15: =IFERROR(K15/E15,0) -> 0 | M15: =IFERROR(SUM('Jan 27'!I5:'Jan 27'!I115),0) -> 0 | N15: =IFERROR(COUNTA('Jan 27'!C5:'Jan 27'!C115),0) -> 0
A16: Feb 2027 | B16: =IFERROR('Feb 27'!G116,0) -> 0 | C16: =IFERROR('Feb 27'!H116,0) -> 0 | D16: =IFERROR('Feb 27'!J116,0) -> 0 | E16: =IFERROR('Feb 27'!H130,0) -> 0 | F16: =IFERROR('Feb 27'!K116+'Feb 27'!L116+'Feb 27'!M116+'Feb 27'!N116+'Feb 27'!O116+'Feb 27'!P116+'Feb 27'!Q116+'Feb 27'!R116+'Feb 27'!S116+'Feb 27'!T116+'Feb 27'!U116,0) -> 0 | G16: =IFERROR('Feb 27'!AB116,0) -> 0 | H16: =IFERROR('Feb 27'!H171,0) -> 0 | I16: =IFERROR(SUMIF('Feb 27'!F5:'Feb 27'!F115,"Own",'Feb 27'!X5:'Feb 27'!X115),0) -> 0 | J16: =IFERROR(SUMIF('Feb 27'!F5:'Feb 27'!F115,"Rented",'Feb 27'!X5:'Feb 27'!X115),0) -> 0 | K16: =IFERROR('Feb 27'!H173,0) -> 0 | L16: =IFERROR(K16/E16,0) -> 0 | M16: =IFERROR(SUM('Feb 27'!I5:'Feb 27'!I115),0) -> 0 | N16: =IFERROR(COUNTA('Feb 27'!C5:'Feb 27'!C115),0) -> 0
A17: Mar 2027 | B17: =IFERROR('Mar 27'!G116,0) -> 0 | C17: =IFERROR('Mar 27'!H116,0) -> 0 | D17: =IFERROR('Mar 27'!J116,0) -> 0 | E17: =IFERROR('Mar 27'!H130,0) -> 0 | F17: =IFERROR('Mar 27'!K116+'Mar 27'!L116+'Mar 27'!M116+'Mar 27'!N116+'Mar 27'!O116+'Mar 27'!P116+'Mar 27'!Q116+'Mar 27'!R116+'Mar 27'!S116+'Mar 27'!T116+'Mar 27'!U116,0) -> 0 | G17: =IFERROR('Mar 27'!AB116,0) -> 0 | H17: =IFERROR('Mar 27'!H171,0) -> 0 | I17: =IFERROR(SUMIF('Mar 27'!F5:'Mar 27'!F115,"Own",'Mar 27'!X5:'Mar 27'!X115),0) -> 0 | J17: =IFERROR(SUMIF('Mar 27'!F5:'Mar 27'!F115,"Rented",'Mar 27'!X5:'Mar 27'!X115),0) -> 0 | K17: =IFERROR('Mar 27'!H173,0) -> 0 | L17: =IFERROR(K17/E17,0) -> 0 | M17: =IFERROR(SUM('Mar 27'!I5:'Mar 27'!I115),0) -> 0 | N17: =IFERROR(COUNTA('Mar 27'!C5:'Mar 27'!C115),0) -> 0
A18: ANNUAL TOTAL | B18: =SUM(B6:B17) -> 18980 | C18: =SUM(C6:C17) -> 17825 | D18: =SUM(D6:D17) -> 0 | E18: =SUM(E6:E17) -> 36805 | F18: =SUM(F6:F17) -> 9550 | G18: =SUM(G6:G17) -> 0 | H18: =SUM(H6:H17) -> 9550 | I18: =SUM(I6:I17) -> 24895 | ... K18: =SUM(K6:K17) -> 27255 | L18: =IFERROR(K18/E18,0) -> 0.74052439 | M18: =SUM(M6:M17) -> 150 | N18: =SUM(N6:N17) -> 5

Sheet Settings
A2: ANCL LOGISTICS · SETTINGS & MASTER DATA · FY 2026–27
A4: Fill this sheet ONCE. All monthly sheets auto-read from here.
A6: OWN VEHICLES (6)
A7: # | B7: Vehicle No. | C7: Model / Type | D7: Driver Name | E7: EMI (₹/mo) | F7: Insurance Expiry | G7: Permit Expiry | H7: FC Expiry | I7: Fuel | J7: Notes
A8: 1 | B8: KA-XX-7195 | C8: Truck | D8: Sharanu | E8: 3318 | I8: Diesel
A9: 2 | B9: KA-XX-4608 | C9: Truck | D9: Manju K | E9: 15070 | I9: Diesel
A10: 3 | B10: KA-XX-6421 | C10: Truck | D10: Rafiq | E10: 16141 | I10: Diesel
A11: 4 | B11: KA-XX-8660 | C11: Truck | D11: Sachin | E11: 15658 | I11: Diesel
A12: 5 | B12: KA-XX-1288 | C12: Truck | D12: Rahul | E12: 8840 | I12: Diesel
A13: 6 | B13: KA-XX-262 | C13: Truck | D13: Rasul | E13: 15499 | I13: Diesel
A15: RENTED / ATTACHED VEHICLES (4)
A16: # | B16: Vehicle No. | C16: Model / Type | D16: Owner/Driver | E16: Agreed Rate (₹) | F16: Commission % | G16: Contract From | H16: Contract To | I16: Pay Terms | J16: Notes
A17: 1 | B17: KA-XX-467 | C17: Lorry | D17: Manju M | I17: Per Trip
A18: 2 | B18: KA-XX-7559 | C18: Lorry | D18: Adil | I18: Per Trip
A19: 3 | B19: KA-XX-8662 | C19: Lorry | D19: Manju MLP | I19: Per Trip
A20: 4 | B20: KA-XX-ATTACH | C20: Various | D20: Attach/Owner | I20: Per Trip
A22: DEFAULT BHATTA RATES (₹ per trip)
A23: Driver | B23: Vehicle | C23: Bhatta Rate (₹) | D23: Notes
A24: Sharanu | B24: KA-XX-7195 | C24: 600
A25: Manju K | B25: KA-XX-4608 | C25: 600
A26: Rafiq | B26: KA-XX-6421 | C26: 600
A27: Sachin | B27: KA-XX-8660 | C27: 600
A28: Rahul | B28: KA-XX-1288 | C28: 600
A29: Rasul | B29: KA-XX-262 | C29: 600
A31: OVERHEAD CATEGORY LABELS (edit col B to rename in all sheets)
A32: 1 | B32: Diesel MLP / Bulk | C32: ← Edit label in col B
A33: 2 | B33: Driver Salaries | C33: ← Edit label in col B
A34: 3 | B34: Vehicle EMI - 7195 | C34: ← Edit label in col B
A35: 4 | B35: Vehicle EMI - 4608 | C35: ← Edit label in col B
A36: 5 | B36: Vehicle EMI - 6421 | C36: ← Edit label in col B
A37: 6 | B37: Vehicle EMI - 8660 | C37: ← Edit label in col B
A38: 7 | B38: Vehicle EMI - 1288 | C38: ← Edit label in col B
A39: 8 | B39: Vehicle EMI - 262 | C39: ← Edit label in col B
A40: 9 | B40: Vehicle EMI - New Vehicle | C40: ← Edit label in col B
A41: 10 | B41: Vehicle Maintenance | C41: ← Edit label in col B
A42: 11 | B42: Shop Rent | C42: ← Edit label in col B
A43: 12 | B43: Electricity & Bills | C43: ← Edit label in col B
... A54: 23 | B54: Misc 6 | C54: ← Edit label in col B

Sheet Apr 26
A2: ANCL LOGISTICS · MONTHLY TRIP & ACCOUNTS LOG · APR 2026
A3: 🟩 Green = Income 🟥 Red = Expenses 🟦 Blue = Auto-calculated 🟨 Enter here | Pending Freight = manual entry only | O3: Own Vehicle: Trip Profit = (Rev+Recd+Adj) − (Bhatta+Hamali+…+Misc3) | Rented Vehicle: Trip Profit = Received + Attach Comm | AA3: FIXED / OVERHEAD EXPENSES (enter once per month)
A4: S.No | B4: Date | C4: TS # | D4: Vehicle No. | E4: Driver | F4: Type (Own/Rented) | G4: Revenue (To Pay ₹) | H4: Received (Paid ₹) | I4: Pending Freight ₹ | J4: Return / Adj ₹ | K4: Bhatta ₹ | L4: Hamali ₹ | M4: Diesel HBL ₹ | N4: Attach Comm ₹ | O4: Diesel MLP ₹ | P4: Tea / Snacks ₹ | Q4: Vehicle Maint ₹ | R4: Salary ₹ | S4: Misc 1 ₹ | T4: Misc 2 ₹ | U4: Misc 3 ₹ | V4: Trip Revenue (auto) ₹ | W4: Trip Expenses (auto) ₹ | X4: Trip Profit (auto) ₹ | Y4: Notes / Description | AA4: Overhead Category | AB4: Amount ₹ | AC4: Date | AD4: Description / Explanation
A5: 1 | B5: 46113 | C5: 2 | D5: 1288 | E5: SHIVU | F5: Own | G5: 3400 | H5: =1200+660+24*60+2530 -> 5830 | K5: 600 | L5: 150 | M5: 2930 | V5: =IF(F5="Own",IFERROR(IFERROR(G5,0)+IFERROR(H5,0)+IFERROR(J5,0),0),IF(F5="Rented",IFERROR(IFERROR(H5,0)+IFERROR(N5,0),0),"")) -> 9230 | W5: =IF(F5="Own",IFERROR(IFERROR(K5,0)+IFERROR(L5,0)+IFERROR(M5,0)+IFERROR(N5,0)+IFERROR(O5,0)+IFERROR(P5,0)+IFERROR(Q5,0)+IFERROR(R5,0)+IFERROR(S5,0)+IFERROR(T5,0)+IFERROR(U5,0),0),IF(F5="Rented",0,"")) -> 3680 | X5: =IF(F5="Own",IFERROR(V5-W5,0),IF(F5="Rented",IFERROR(V5,0),"")) -> 5550 | AA5: =Settings!B32 -> Diesel MLP / Bulk
A6: 2 | B6: 46113 | C6: 1 | D6: 467 | E6: YAMANAPPA | F6: Own | G6: 3450 | H6: =885+60*70+80+1100 -> 6265 | I6: 150 | K6: 800 | L6: 150 | M6: 1700 | V6: =IF(F6="Own",IFERROR(IFERROR(G6,0)+IFERROR(H6,0)+IFERROR(J6,0),0),IF(F6="Rented",IFERROR(IFERROR(H6,0)+IFERROR(N6,0),0),"")) -> 9715 | W6: =IF(F6="Own",IFERROR(IFERROR(K6,0)+IFERROR(L6,0)+IFERROR(M6,0)+IFERROR(N6,0)+IFERROR(O6,0)+IFERROR(P6,0)+IFERROR(Q6,0)+IFERROR(R6,0)+IFERROR(S6,0)+IFERROR(T6,0)+IFERROR(U6,0),0),IF(F6="Rented",0,"")) -> 2650 | X6: =IF(F6="Own",IFERROR(V6-W6,0),IF(F6="Rented",IFERROR(V6,0),"")) -> 7065 | AA6: =Settings!B33 -> Driver Salaries
A7: 3 | C7: 3 | D7: 1785 | E7: SALEEM | F7: Rented | H7: 2080 | N7: -280 | V7: =IF(F7="Own",IFERROR(IFERROR(G7,0)+IFERROR(H7,0)+IFERROR(J7,0),0),IF(F7="Rented",IFERROR(IFERROR(H7,0)+IFERROR(N7,0),0),"")) -> 1800 | W7: =IF(F7="Own",IFERROR(IFERROR(K7,0)+IFERROR(L7,0)+IFERROR(M7,0)+IFERROR(N7,0)+IFERROR(O7,0)+IFERROR(P7,0)+IFERROR(Q7,0)+IFERROR(R7,0)+IFERROR(S7,0)+IFERROR(T7,0)+IFERROR(U7,0),0),IF(F7="Rented",0,"")) -> 0 | X7: =IF(F7="Own",IFERROR(V7-W7,0),IF(F7="Rented",IFERROR(V7,0),"")) -> 1800 | AA7: =Settings!B34 -> Vehicle EMI - 7195
A8: 4 | C8: 4 | D8: 6421 | E8: RAFIQ | F8: Own | G8: 7560 | H8: 1010 | K8: 600 | M8: 2300 | V8: =IF(F8="Own",IFERROR(IFERROR(G8,0)+IFERROR(H8,0)+IFERROR(J8,0),0),IF(F8="Rented",IFERROR(IFERROR(H8,0)+IFERROR(N8,0),0),"")) -> 8570 | W8: =IF(F8="Own",IFERROR(IFERROR(K8,0)+IFERROR(L8,0)+IFERROR(M8,0)+IFERROR(N8,0)+IFERROR(O8,0)+IFERROR(P8,0)+IFERROR(Q8,0)+IFERROR(R8,0)+IFERROR(S8,0)+IFERROR(T8,0)+IFERROR(U8,0),0),IF(F8="Rented",0,"")) -> 2900 | X8: =IF(F8="Own",IFERROR(V8-W8,0),IF(F8="Rented",IFERROR(V8,0),"")) -> 5670 | AA8: =Settings!B35 -> Vehicle EMI - 4608
A9: 5 | C9: 5 | D9: 8660 | E9: VINOD | F9: Own | G9: 4570 | H9: =14*50+250+1690 -> 2640 | K9: 600 | V9: =IF(F9="Own",IFERROR(IFERROR(G9,0)+IFERROR(H9,0)+IFERROR(J9,0),0),IF(F9="Rented",IFERROR(IFERROR(H9,0)+IFERROR(N9,0),0),"")) -> 7210 | W9: =IF(F9="Own",IFERROR(IFERROR(K9,0)+IFERROR(L9,0)+IFERROR(M9,0)+IFERROR(N9,0)+IFERROR(O9,0)+IFERROR(P9,0)+IFERROR(Q9,0)+IFERROR(R9,0)+IFERROR(S9,0)+IFERROR(T9,0)+IFERROR(U9,0),0),IF(F9="Rented",0,"")) -> 600 | X9: =IF(F9="Own",IFERROR(V9-W9,0),IF(F9="Rented",IFERROR(V9,0),"")) -> 6610 | AA9: =Settings!B36 -> Vehicle EMI - 6421
A10: 6 | V10: =IF(F10="Own",IFERROR(IFERROR(G10,0)+IFERROR(H10,0)+IFERROR(J10,0),0),IF(F10="Rented",IFERROR(IFERROR(H10,0)+IFERROR(N10,0),0),"")) | W10: =IF(F10="Own",IFERROR(IFERROR(K10,0)+IFERROR(L10,0)+IFERROR(M10,0)+IFERROR(N10,0)+IFERROR(O10,0)+IFERROR(P10,0)+IFERROR(Q10,0)+IFERROR(R10,0)+IFERROR(S10,0)+IFERROR(T10,0)+IFERROR(U10,0),0),IF(F10="Rented",0,"")) | X10: =IF(F10="Own",IFERROR(V10-W10,0),IF(F10="Rented",IFERROR(V10,0),"")) | AA10: =Settings!B37 -> Vehicle EMI - 8660
A11: 7 | V11: =IF(F11="Own",IFERROR(IFERROR(G11,0)+IFERROR(H11,0)+IFERROR(J11,0),0),IF(F11="Rented",IFERROR(IFERROR(H11,0)+IFERROR(N11,0),0),"")) | W11: =IF(F11="Own",IFERROR(IFERROR(K11,0)+IFERROR(L11,0)+IFERROR(M11,0)+IFERROR(N11,0)+IFERROR(O11,0)+IFERROR(P11,0)+IFERROR(Q11,0)+IFERROR(R11,0)+IFERROR(S11,0)+IFERROR(T11,0)+IFERROR(U11,0),0),IF(F11="Rented",0,"")) | X11: =IF(F11="Own",IFERROR(V11-W11,0),IF(F11="Rented",IFERROR(V11,0),"")) | AA11: =Settings!B38 -> Vehicle EMI - 1288
A12: 8 | V12: =IF(F12="Own",IFERROR(IFERROR(G12,0)+IFERROR(H12,0)+IFERROR(J12,0),0),IF(F12="Rented",IFERROR(IFERROR(H12,0)+IFERROR(N12,0),0),"")) | W12: =IF(F12="Own",IFERROR(IFERROR(K12,0)+IFERROR(L12,0)+IFERROR(M12,0)+IFERROR(N12,0)+IFERROR(O12,0)+IFERROR(P12,0)+IFERROR(Q12,0)+IFERROR(R12,0)+IFERROR(S12,0)+IFERROR(T12,0)+IFERROR(U12,0),0),IF(F12="Rented",0,"")) | X12: =IF(F12="Own",IFERROR(V12-W12,0),IF(F12="Rented",IFERROR(V12,0),"")) | AA12: =Settings!B39 -> Vehicle EMI - 262
A13: 9 | V13: =IF(F13="Own",IFERROR(IFERROR(G13,0)+IFERROR(H13,0)+IFERROR(J13,0),0),IF(F13="Rented",IFERROR(IFERROR(H13,0)+IFERROR(N13,0),0),"")) | W13: =IF(F13="Own",IFERROR(IFERROR(K13,0)+IFERROR(L13,0)+IFERROR(M13,0)+IFERROR(N13,0)+IFERROR(O13,0)+IFERROR(P13,0)+IFERROR(Q13,0)+IFERROR(R13,0)+IFERROR(S13,0)+IFERROR(T13,0)+IFERROR(U13,0),0),IF(F13="Rented",0,"")) | X13: =IF(F13="Own",IFERROR(V13-W13,0),IF(F13="Rented",IFERROR(V13,0),"")) | AA13: =Settings!B40 -> Vehicle EMI - New Vehicle
A14: 10 | V14: =IF(F14="Own",IFERROR(IFERROR(G14,0)+IFERROR(H14,0)+IFERROR(J14,0),0),IF(F14="Rented",IFERROR(IFERROR(H14,0)+IFERROR(N14,0),0),"")) | W14: =IF(F14="Own",IFERROR(IFERROR(K14,0)+IFERROR(L14,0)+IFERROR(M14,0)+IFERROR(N14,0)+IFERROR(O14,0)+IFERROR(P14,0)+IFERROR(Q14,0)+IFERROR(R14,0)+IFERROR(S14,0)+IFERROR(T14,0)+IFERROR(U14,0),0),IF(F14="Rented",0,"")) | X14: =IF(F14="Own",IFERROR(V14-W14,0),IF(F14="Rented",IFERROR(V14,0),"")) | AA14: =Settings!B41 -> Vehicle Maintenance
A15: 11 | V15: =IF(F15="Own",IFERROR(IFERROR(G15,0)+IFERROR(H15,0)+IFERROR(J15,0),0),IF(F15="Rented",IFERROR(IFERROR(H15,0)+IFERROR(N15,0),0),"")) | W15: =IF(F15="Own",IFERROR(IFERROR(K15,0)+IFERROR(L15,0)+IFERROR(M15,0)+IFERROR(N15,0)+IFERROR(O15,0)+IFERROR(P15,0)+IFERROR(Q15,0)+IFERROR(R15,0)+IFERROR(S15,0)+IFERROR(T15,0)+IFERROR(U15,0),0),IF(F15="Rented",0,"")) | X15: =IF(F15="Own",IFERROR(V15-W15,0),IF(F15="Rented",IFERROR(V15,0),"")) | AA15: =Settings!B42 -> Shop Rent
A16: 12 | V16: =IF(F16="Own",IFERROR(IFERROR(G16,0)+IFERROR(H16,0)+IFERROR(J16,0),0),IF(F16="Rented",IFERROR(IFERROR(H16,0)+IFERROR(N16,0),0),"")) | W16: =IF(F16="Own",IFERROR(IFERROR(K16,0)+IFERROR(L16,0)+IFERROR(M16,0)+IFERROR(N16,0)+IFERROR(O16,0)+IFERROR(P16,0)+IFERROR(Q16,0)+IFERROR(R16,0)+IFERROR(S16,0)+IFERROR(T16,0)+IFERROR(U16,0),0),IF(F16="Rented",0,"")) | X16: =IF(F16="Own",IFERROR(V16-W16,0),IF(F16="Rented",IFERROR(V16,0),"")) | AA16: =Settings!B43 -> Electricity & Bills
A17: 13 | V17: =IF(F17="Own",IFERROR(IFERROR(G17,0)+IFERROR(H17,0)+IFERROR(J17,0),0),IF(F17="Rented",IFERROR(IFERROR(H17,0)+IFERROR(N17,0),0),"")) | W17: =IF(F17="Own",IFERROR(IFERROR(K17,0)+IFERROR(L17,0)+IFERROR(M17,0)+IFERROR(N17,0)+IFERROR(O17,0)+IFERROR(P17,0)+IFERROR(Q17,0)+IFERROR(R17,0)+IFERROR(S17,0)+IFERROR(T17,0)+IFERROR(U17,0),0),IF(F17="Rented",0,"")) | X17: =IF(F17="Own",IFERROR(V17-W17,0),IF(F17="Rented",IFERROR(V17,0),"")) | AA17: =Settings!B44 -> Chits / Pigmy
A18: 14 | V18: =IF(F18="Own",IFERROR(IFERROR(G18,0)+IFERROR(H18,0)+IFERROR(J18,0),0),IF(F18="Rented",IFERROR(IFERROR(H18,0)+IFERROR(N18,0),0),"")) | W18: =IF(F18="Own",IFERROR(IFERROR(K18,0)+IFERROR(L18,0)+IFERROR(M18,0)+IFERROR(N18,0)+IFERROR(O18,0)+IFERROR(P18,0)+IFERROR(Q18,0)+IFERROR(R18,0)+IFERROR(S18,0)+IFERROR(T18,0)+IFERROR(U18,0),0),IF(F18="Rented",0,"")) | X18: =IF(F18="Own",IFERROR(V18-W18,0),IF(F18="Rented",IFERROR(V18,0),"")) | AA18: =Settings!B45 -> LR Printing & Stationery
A19: 15 | V19: =IF(F19="Own",IFERROR(IFERROR(G19,0)+IFERROR(H19,0)+IFERROR(J19,0),0),IF(F19="Rented",IFERROR(IFERROR(H19,0)+IFERROR(N19,0),0),"")) | W19: =IF(F19="Own",IFERROR(IFERROR(K19,0)+IFERROR(L19,0)+IFERROR(M19,0)+IFERROR(N19,0)+IFERROR(O19,0)+IFERROR(P19,0)+IFERROR(Q19,0)+IFERROR(R19,0)+IFERROR(S19,0)+IFERROR(T19,0)+IFERROR(U19,0),0),IF(F19="Rented",0,"")) | X19: =IF(F19="Own",IFERROR(V19-W19,0),IF(F19="Rented",IFERROR(V19,0),"")) | AA19: =Settings!B46 -> Tea / Snacks / Food
A20: 16 | V20: =IF(F20="Own",IFERROR(IFERROR(G20,0)+IFERROR(H20,0)+IFERROR(J20,0),0),IF(F20="Rented",IFERROR(IFERROR(H20,0)+IFERROR(N20,0),0),"")) | W20: =IF(F20="Own",IFERROR(IFERROR(K20,0)+IFERROR(L20,0)+IFERROR(M20,0)+IFERROR(N20,0)+IFERROR(O20,0)+IFERROR(P20,0)+IFERROR(Q20,0)+IFERROR(R20,0)+IFERROR(S20,0)+IFERROR(T20,0)+IFERROR(U20,0),0),IF(F20="Rented",0,"")) | X20: =IF(F20="Own",IFERROR(V20-W20,0),IF(F20="Rented",IFERROR(V20,0),"")) | AA20: =Settings!B47 -> Commission (Office)
A21: 17 | V21: =IF(F21="Own",IFERROR(IFERROR(G21,0)+IFERROR(H21,0)+IFERROR(J21,0),0),IF(F21="Rented",IFERROR(IFERROR(H21,0)+IFERROR(N21,0),0),"")) | W21: =IF(F21="Own",IFERROR(IFERROR(K21,0)+IFERROR(L21,0)+IFERROR(M21,0)+IFERROR(N21,0)+IFERROR(O21,0)+IFERROR(P21,0)+IFERROR(Q21,0)+IFERROR(R21,0)+IFERROR(S21,0)+IFERROR(T21,0)+IFERROR(U21,0),0),IF(F21="Rented",0,"")) | X21: =IF(F21="Own",IFERROR(V21-W21,0),IF(F21="Rented",IFERROR(V21,0),"")) | AA21: =Settings!B48 -> Profit Encashment
... A27: 23 | V27: =IF(F27="Own",IFERROR(IFERROR(G27,0)+IFERROR(H27,0)+IFERROR(J27,0),0),IF(F27="Rented",IFERROR(IFERROR(H27,0)+IFERROR(N27,0),0),"")) | W27: =IF(F27="Own",IFERROR(IFERROR(K27,0)+IFERROR(L27,0)+IFERROR(M27,0)+IFERROR(N27,0)+IFERROR(O27,0)+IFERROR(P27,0)+IFERROR(Q27,0)+IFERROR(R27,0)+IFERROR(S27,0)+IFERROR(T27,0)+IFERROR(U27,0),0),IF(F27="Rented",0,"")) | X27: =IF(F27="Own",IFERROR(V27-W27,0),IF(F27="Rented",IFERROR(V27,0),"")) | AA27: =Settings!B54 -> Misc 6
A28: 24 | V28: =IF(F28="Own",IFERROR(IFERROR(G28,0)+IFERROR(H28,0)+IFERROR(J28,0),0),IF(F28="Rented",IFERROR(IFERROR(H28,0)+IFERROR(N28,0),0),"")) | W28: =IF(F28="Own",IFERROR(IFERROR(K28,0)+IFERROR(L28,0)+IFERROR(M28,0)+IFERROR(N28,0)+IFERROR(O28,0)+IFERROR(P28,0)+IFERROR(Q28,0)+IFERROR(R28,0)+IFERROR(S28,0)+IFERROR(T28,0)+IFERROR(U28,0),0),IF(F28="Rented",0,"")) | X28: =IF(F28="Own",IFERROR(V28-W28,0),IF(F28="Rented",IFERROR(V28,0),""))
A29: 25 | V29: =IF(F29="Own",IFERROR(IFERROR(G29,0)+IFERROR(H29,0)+IFERROR(J29,0),0),IF(F29="Rented",IFERROR(IFERROR(H29,0)+IFERROR(N29,0),0),"")) | W29: =IF(F29="Own",IFERROR(IFERROR(K29,0)+IFERROR(L29,0)+IFERROR(M29,0)+IFERROR(N29,0)+IFERROR(O29,0)+IFERROR(P29,0)+IFERROR(Q29,0)+IFERROR(R29,0)+IFERROR(S29,0)+IFERROR(T29,0)+IFERROR(U29,0),0),IF(F29="Rented",0,"")) | X29: =IF(F29="Own",IFERROR(V29-W29,0),IF(F29="Rented",IFERROR(V29,0),""))
A30: 26 | V30: =IF(F30="Own",IFERROR(IFERROR(G30,0)+IFERROR(H30,0)+IFERROR(J30,0),0),IF(F30="Rented",IFERROR(IFERROR(H30,0)+IFERROR(N30,0),0),"")) | W30: =IF(F30="Own",IFERROR(IFERROR(K30,0)+IFERROR(L30,0)+IFERROR(M30,0)+IFERROR(N30,0)+IFERROR(O30,0)+IFERROR(P30,0)+IFERROR(Q30,0)+IFERROR(R30,0)+IFERROR(S30,0)+IFERROR(T30,0)+IFERROR(U30,0),0),IF(F30="Rented",0,"")) | X30: =IF(F30="Own",IFERROR(V30-W30,0),IF(F30="Rented",IFERROR(V30,0),""))
A31: 27 | V31: =IF(F31="Own",IFERROR(IFERROR(G31,0)+IFERROR(H31,0)+IFERROR(J31,0),0),IF(F31="Rented",IFERROR(IFERROR(H31,0)+IFERROR(N31,0),0),"")) | W31: =IF(F31="Own",IFERROR(IFERROR(K31,0)+IFERROR(L31,0)+IFERROR(M31,0)+IFERROR(N31,0)+IFERROR(O31,0)+IFERROR(P31,0)+IFERROR(Q31,0)+IFERROR(R31,0)+IFERROR(S31,0)+IFERROR(T31,0)+IFERROR(U31,0),0),IF(F31="Rented",0,"")) | X31: =IF(F31="Own",IFERROR(V31-W31,0),IF(F31="Rented",IFERROR(V31,0),""))
A32: 28 | V32: =IF(F32="Own",IFERROR(IFERROR(G32,0)+IFERROR(H32,0)+IFERROR(J32,0),0),IF(F32="Rented",IFERROR(IFERROR(H32,0)+IFERROR(N32,0),0),"")) | W32: =IF(F32="Own",IFERROR(IFERROR(K32,0)+IFERROR(L32,0)+IFERROR(M32,0)+IFERROR(N32,0)+IFERROR(O32,0)+IFERROR(P32,0)+IFERROR(Q32,0)+IFERROR(R32,0)+IFERROR(S32,0)+IFERROR(T32,0)+IFERROR(U32,0),0),IF(F32="Rented",0,"")) | X32: =IF(F32="Own",IFERROR(V32-W32,0),IF(F32="Rented",IFERROR(V32,0),""))
A33: 29 | V33: =IF(F33="Own",IFERROR(IFERROR(G33,0)+IFERROR(H33,0)+IFERROR(J33,0),0),IF(F33="Rented",IFERROR(IFERROR(H33,0)+IFERROR(N33,0),0),"")) | W33: =IF(F33="Own",IFERROR(IFERROR(K33,0)+IFERROR(L33,0)+IFERROR(M33,0)+IFERROR(N33,0)+IFERROR(O33,0)+IFERROR(P33,0)+IFERROR(Q33,0)+IFERROR(R33,0)+IFERROR(S33,0)+IFERROR(T33,0)+IFERROR(U33,0),0),IF(F33="Rented",0,"")) | X33: =IF(F33="Own",IFERROR(V33-W33,0),IF(F33="Rented",IFERROR(V33,0),""))
A34: 30 | V34: =IF(F34="Own",IFERROR(IFERROR(G34,0)+IFERROR(H34,0)+IFERROR(J34,0),0),IF(F34="Rented",IFERROR(IFERROR(H34,0)+IFERROR(N34,0),0),"")) | W34: =IF(F34="Own",IFERROR(IFERROR(K34,0)+IFERROR(L34,0)+IFERROR(M34,0)+IFERROR(N34,0)+IFERROR(O34,0)+IFERROR(P34,0)+IFERROR(Q34,0)+IFERROR(R34,0)+IFERROR(S34,0)+IFERROR(T34,0)+IFERROR(U34,0),0),IF(F34="Rented",0,"")) | X34: =IF(F34="Own",IFERROR(V34-W34,0),IF(F34="Rented",IFERROR(V34,0),""))
A35: 31 | V35: =IF(F35="Own",IFERROR(IFERROR(G35,0)+IFERROR(H35,0)+IFERROR(J35,0),0),IF(F35="Rented",IFERROR(IFERROR(H35,0)+IFERROR(N35,0),0),"")) | W35: =IF(F35="Own",IFERROR(IFERROR(K35,0)+IFERROR(L35,0)+IFERROR(M35,0)+IFERROR(N35,0)+IFERROR(O35,0)+IFERROR(P35,0)+IFERROR(Q35,0)+IFERROR(R35,0)+IFERROR(S35,0)+IFERROR(T35,0)+IFERROR(U35,0),0),IF(F35="Rented",0,"")) | X35: =IF(F35="Own",IFERROR(V35-W35,0),IF(F35="Rented",IFERROR(V35,0),""))
A36: 32 | V36: =IF(F36="Own",IFERROR(IFERROR(G36,0)+IFERROR(H36,0)+IFERROR(J36,0),0),IF(F36="Rented",IFERROR(IFERROR(H36,0)+IFERROR(N36,0),0),"")) | W36: =IF(F36="Own",IFERROR(IFERROR(K36,0)+IFERROR(L36,0)+IFERROR(M36,0)+IFERROR(N36,0)+IFERROR(O36,0)+IFERROR(P36,0)+IFERROR(Q36,0)+IFERROR(R36,0)+IFERROR(S36,0)+IFERROR(T36,0)+IFERROR(U36,0),0),IF(F36="Rented",0,"")) | X36: =IF(F36="Own",IFERROR(V36-W36,0),IF(F36="Rented",IFERROR(V36,0),""))
A37: 33 | V37: =IF(F37="Own",IFERROR(IFERROR(G37,0)+IFERROR(H37,0)+IFERROR(J37,0),0),IF(F37="Rented",IFERROR(IFERROR(H37,0)+IFERROR(N37,0),0),"")) | W37: =IF(F37="Own",IFERROR(IFERROR(K37,0)+IFERROR(L37,0)+IFERROR(M37,0)+IFERROR(N37,0)+IFERROR(O37,0)+IFERROR(P37,0)+IFERROR(Q37,0)+IFERROR(R37,0)+IFERROR(S37,0)+IFERROR(T37,0)+IFERROR(U37,0),0),IF(F37="Rented",0,"")) | X37: =IF(F37="Own",IFERROR(V37-W37,0),IF(F37="Rented",IFERROR(V37,0),""))
A38: 34 | V38: =IF(F38="Own",IFERROR(IFERROR(G38,0)+IFERROR(H38,0)+IFERROR(J38,0),0),IF(F38="Rented",IFERROR(IFERROR(H38,0)+IFERROR(N38,0),0),"")) | W38: =IF(F38="Own",IFERROR(IFERROR(K38,0)+IFERROR(L38,0)+IFERROR(M38,0)+IFERROR(N38,0)+IFERROR(O38,0)+IFERROR(P38,0)+IFERROR(Q38,0)+IFERROR(R38,0)+IFERROR(S38,0)+IFERROR(T38,0)+IFERROR(U38,0),0),IF(F38="Rented",0,"")) | X38: =IF(F38="Own",IFERROR(V38-W38,0),IF(F38="Rented",IFERROR(V38,0),""))
A39: 35 | V39: =IF(F39="Own",IFERROR(IFERROR(G39,0)+IFERROR(H39,0)+IFERROR(J39,0),0),IF(F39="Rented",IFERROR(IFERROR(H39,0)+IFERROR(N39,0),0),"")) | W39: =IF(F39="Own",IFERROR(IFERROR(K39,0)+IFERROR(L39,0)+IFERROR(M39,0)+IFERROR(N39,0)+IFERROR(O39,0)+IFERROR(P39,0)+IFERROR(Q39,0)+IFERROR(R39,0)+IFERROR(S39,0)+IFERROR(T39,0)+IFERROR(U39,0),0),IF(F39="Rented",0,"")) | X39: =IF(F39="Own",IFERROR(V39-W39,0),IF(F39="Rented",IFERROR(V39,0),""))
... A115: 111 | V115: =IF(F115="Own",IFERROR(IFERROR(G115,0)+IFERROR(H115,0)+IFERROR(J115,0),0),IF(F115="Rented",IFERROR(IFERROR(H115,0)+IFERROR(N115,0),0),"")) | W115: =IF(F115="Own",IFERROR(IFERROR(K115,0)+IFERROR(L115,0)+IFERROR(M115,0)+IFERROR(N115,0)+IFERROR(O115,0)+IFERROR(P115,0)+IFERROR(Q115,0)+IFERROR(R115,0)+IFERROR(S115,0)+IFERROR(T115,0)+IFERROR(U115,0),0),IF(F115="Rented",0,"")) | X115: =IF(F115="Own",IFERROR(V115-W115,0),IF(F115="Rented",IFERROR(V115,0),""))
A116: TRIP TOTALS | G116: =IFERROR(SUM(G5:G115),0) -> 18980 | H116: =IFERROR(SUM(H5:H115),0) -> 17825 | I116: =IFERROR(SUM(I5:I115),0) -> 150 | J116: =IFERROR(SUM(J5:J115),0) -> 0 | K116: =IFERROR(SUM(K5:K115),0) -> 2600 | L116: =IFERROR(SUM(L5:L115),0) -> 300 | M116: =IFERROR(SUM(M5:M115),0) -> 6930 | N116: =IFERROR(SUM(N5:N115),0) -> -280 | ... X116: =IFERROR(SUM(X5:X115),0) -> 26695 | Y116: =COUNTA(C5:C115)&" trips" -> 5 trips | AA116: OVERHEAD TOTAL | AB116: =IFERROR(SUM(AB5:AB27),0) -> 0
A118: VEHICLE TYPE SUMMARY (auto-calculated from Type column F)
B119: Type | C119: Revenue ₹ | D119: Received ₹ | E119: Return/Adj ₹ | F119: Pending Freight ₹ | G119: Trip Expenses ₹ | H119: Trip Profit ₹ | I119: Trips
B120: OWN VEHICLES | C120: =IFERROR(SUMIF(F5:F115,"Own",G5:G115),0) -> 18980 | D120: =IFERROR(SUMIF(F5:F115,"Own",H5:H115),0) -> 15745 | E120: =IFERROR(SUMIF(F5:F115,"Own",J5:J115),0) -> 0 | F120: =IFERROR(SUMIF(F5:F115,"Own",I5:I115),0) -> 150 | G120: =IFERROR(SUMIF(F5:F115,"Own",W5:W115),0) -> 9830 | H120: =IFERROR(SUMIF(F5:F115,"Own",X5:X115),0) -> 24895 | I120: =IFERROR(COUNTIF(F5:F115,"Own"),0) -> 4
B121: RENTED VEHICLES | C121: =IFERROR(SUMIF(F5:F115,"Rented",G5:G115),0) -> 0 | D121: =IFERROR(SUMIF(F5:F115,"Rented",H5:H115),0) -> 2080 | E121: =IFERROR(SUMIF(F5:F115,"Rented",J5:J115),0) -> 0 | F121: =IFERROR(SUMIF(F5:F115,"Rented",I5:I115),0) -> 0 | G121: =IFERROR(SUMIF(F5:F115,"Rented",W5:W115),0) -> 0 | H121: =IFERROR(SUMIF(F5:F115,"Rented",X5:X115),0) -> 1800 | I121: =IFERROR(COUNTIF(F5:F115,"Rented"),0) -> 1
B122: TOTAL | C122: =C120+C121 -> 18980 | D122: =D120+D121 -> 17825 | E122: =E120+E121 -> 0 | F122: =F120+F121 -> 150 | G122: =G120+G121 -> 9830 | H122: =H120+H121 -> 26695 | I122: =I120+I121 -> 5
...

Sheet May 26
A2: ANCL LOGISTICS · MONTHLY TRIP & ACCOUNTS LOG · MAY 2026
A3: 🟩 Green = Income 🟥 Red = Expenses 🟦 Blue = Auto-calculated 🟨 Enter here | Pending Freight = manual entry only | O3: Own Vehicle: Trip Profit = (Rev+Recd+Adj) − (Bhatta+Hamali+…+Misc3) | Rented Vehicle: Trip Profit = Received + Attach Comm | AA3: FIXED / OVERHEAD EXPENSES (enter once per month)
A4: S.No | B4: Date | C4: TS # | D4: Vehicle No. | E4: Driver | F4: Type (Own/Rented) | G4: Revenue (To Pay ₹) | H4: Received (Paid ₹) | I4: Pending Freight ₹ | J4: Return / Adj ₹ | K4: Bhatta ₹ | L4: Hamali ₹ | M4: Diesel HBL ₹ | N4: Attach Comm ₹ | O4: Diesel MLP ₹ | P4: Tea / Snacks ₹ | Q4: Vehicle Maint ₹ | R4: Salary ₹ | S4: Misc 1 ₹ | T4: Misc 2 ₹ | U4: Misc 3 ₹ | V4: Trip Revenue (auto) ₹ | W4: Trip Expenses (auto) ₹ | X4: Trip Profit (auto) ₹ | Y4: Notes / Description | AA4: Overhead Category | AB4: Amount ₹ | AC4: Date | AD4: Description / Explanation
A5: 1 | V5: =IF(F5="Own",IFERROR(IFERROR(G5,0)+IFERROR(H5,0)+IFERROR(J5,0),0),IF(F5="Rented",IFERROR(IFERROR(H5,0)+IFERROR(N5,0),0),"")) | W5: =IF(F5="Own",IFERROR(IFERROR(K5,0)+IFERROR(L5,0)+IFERROR(M5,0)+IFERROR(N5,0)+IFERROR(O5,0)+IFERROR(P5,0)+IFERROR(Q5,0)+IFERROR(R5,0)+IFERROR(S5,0)+IFERROR(T5,0)+IFERROR(U5,0),0),IF(F5="Rented",0,"")) | X5: =IF(F5="Own",IFERROR(V5-W5,0),IF(F5="Rented",IFERROR(V5,0),"")) | AA5: =Settings!B32 -> Diesel MLP / Bulk
A6: 2 | V6: =IF(F6="Own",IFERROR(IFERROR(G6,0)+IFERROR(H6,0)+IFERROR(J6,0),0),IF(F6="Rented",IFERROR(IFERROR(H6,0)+IFERROR(N6,0),0),"")) | W6: =IF(F6="Own",IFERROR(IFERROR(K6,0)+IFERROR(L6,0)+IFERROR(M6,0)+IFERROR(N6,0)+IFERROR(O6,0)+IFERROR(P6,0)+IFERROR(Q6,0)+IFERROR(R6,0)+IFERROR(S6,0)+IFERROR(T6,0)+IFERROR(U6,0),0),IF(F6="Rented",0,"")) | X6: =IF(F6="Own",IFERROR(V6-W6,0),IF(F6="Rented",IFERROR(V6,0),"")) | AA6: =Settings!B33 -> Driver Salaries
A7: 3 | V7: =IF(F7="Own",IFERROR(IFERROR(G7,0)+IFERROR(H7,0)+IFERROR(J7,0),0),IF(F7="Rented",IFERROR(IFERROR(H7,0)+IFERROR(N7,0),0),"")) | W7: =IF(F7="Own",IFERROR(IFERROR(K7,0)+IFERROR(L7,0)+IFERROR(M7,0)+IFERROR(N7,0)+IFERROR(O7,0)+IFERROR(P7,0)+IFERROR(Q7,0)+IFERROR(R7,0)+IFERROR(S7,0)+IFERROR(T7,0)+IFERROR(U7,0),0),IF(F7="Rented",0,"")) | X7: =IF(F7="Own",IFERROR(V7-W7,0),IF(F7="Rented",IFERROR(V7,0),"")) | AA7: =Settings!B34 -> Vehicle EMI - 7195
A8: 4 | V8: =IF(F8="Own",IFERROR(IFERROR(G8,0)+IFERROR(H8,0)+IFERROR(J8,0),0),IF(F8="Rented",IFERROR(IFERROR(H8,0)+IFERROR(N8,0),0),"")) | W8: =IF(F8="Own",IFERROR(IFERROR(K8,0)+IFERROR(L8,0)+IFERROR(M8,0)+IFERROR(N8,0)+IFERROR(O8,0)+IFERROR(P8,0)+IFERROR(Q8,0)+IFERROR(R8,0)+IFERROR(S8,0)+IFERROR(T8,0)+IFERROR(U8,0),0),IF(F8="Rented",0,"")) | X8: =IF(F8="Own",IFERROR(V8-W8,0),IF(F8="Rented",IFERROR(V8,0),"")) | AA8: =Settings!B35 -> Vehicle EMI - 4608
A9: 5 | V9: =IF(F9="Own",IFERROR(IFERROR(G9,0)+IFERROR(H9,0)+IFERROR(J9,0),0),IF(F9="Rented",IFERROR(IFERROR(H9,0)+IFERROR(N9,0),0),"")) | W9: =IF(F9="Own",IFERROR(IFERROR(K9,0)+IFERROR(L9,0)+IFERROR(M9,0)+IFERROR(N9,0)+IFERROR(O9,0)+IFERROR(P9,0)+IFERROR(Q9,0)+IFERROR(R9,0)+IFERROR(S9,0)+IFERROR(T9,0)+IFERROR(U9,0),0),IF(F9="Rented",0,"")) | X9: =IF(F9="Own",IFERROR(V9-W9,0),IF(F9="Rented",IFERROR(V9,0),"")) | AA9: =Settings!B36 -> Vehicle EMI - 6421
A10: 6 | V10: =IF(F10="Own",IFERROR(IFERROR(G10,0)+IFERROR(H10,0)+IFERROR(J10,0),0),IF(F10="Rented",IFERROR(IFERROR(H10,0)+IFERROR(N10,0),0),"")) | W10: =IF(F10="Own",IFERROR(IFERROR(K10,0)+IFERROR(L10,0)+IFERROR(M10,0)+IFERROR(N10,0)+IFERROR(O10,0)+IFERROR(P10,0)+IFERROR(Q10,0)+IFERROR(R10,0)+IFERROR(S10,0)+IFERROR(T10,0)+IFERROR(U10,0),0),IF(F10="Rented",0,"")) | X10: =IF(F10="Own",IFERROR(V10-W10,0),IF(F10="Rented",IFERROR(V10,0),"")) | AA10: =Settings!B37 -> Vehicle EMI - 8660
A11: 7 | V11: =IF(F11="Own",IFERROR(IFERROR(G11,0)+IFERROR(H11,0)+IFERROR(J11,0),0),IF(F11="Rented",IFERROR(IFERROR(H11,0)+IFERROR(N11,0),0),"")) | W11: =IF(F11="Own",IFERROR(IFERROR(K11,0)+IFERROR(L11,0)+IFERROR(M11,0)+IFERROR(N11,0)+IFERROR(O11,0)+IFERROR(P11,0)+IFERROR(Q11,0)+IFERROR(R11,0)+IFERROR(S11,0)+IFERROR(T11,0)+IFERROR(U11,0),0),IF(F11="Rented",0,"")) | X11: =IF(F11="Own",IFERROR(V11-W11,0),IF(F11="Rented",IFERROR(V11,0),"")) | AA11: =Settings!B38 -> Vehicle EMI - 1288
A12: 8 | V12: =IF(F12="Own",IFERROR(IFERROR(G12,0)+IFERROR(H12,0)+IFERROR(J12,0),0),IF(F12="Rented",IFERROR(IFERROR(H12,0)+IFERROR(N12,0),0),"")) | W12: =IF(F12="Own",IFERROR(IFERROR(K12,0)+IFERROR(L12,0)+IFERROR(M12,0)+IFERROR(N12,0)+IFERROR(O12,0)+IFERROR(P12,0)+IFERROR(Q12,0)+IFERROR(R12,0)+IFERROR(S12,0)+IFERROR(T12,0)+IFERROR(U12,0),0),IF(F12="Rented",0,"")) | X12: =IF(F12="Own",IFERROR(V12-W12,0),IF(F12="Rented",IFERROR(V12,0),"")) | AA12: =Settings!B39 -> Vehicle EMI - 262
A13: 9 | V13: =IF(F13="Own",IFERROR(IFERROR(G13,0)+IFERROR(H13,0)+IFERROR(J13,0),0),IF(F13="Rented",IFERROR(IFERROR(H13,0)+IFERROR(N13,0),0),"")) | W13: =IF(F13="Own",IFERROR(IFERROR(K13,0)+IFERROR(L13,0)+IFERROR(M13,0)+IFERROR(N13,0)+IFERROR(O13,0)+IFERROR(P13,0)+IFERROR(Q13,0)+IFERROR(R13,0)+IFERROR(S13,0)+IFERROR(T13,0)+IFERROR(U13,0),0),IF(F13="Rented",0,"")) | X13: =IF(F13="Own",IFERROR(V13-W13,0),IF(F13="Rented",IFERROR(V13,0),"")) | AA13: =Settings!B40 -> Vehicle EMI - New Vehicle
A14: 10 | V14: =IF(F14="Own",IFERROR(IFERROR(G14,0)+IFERROR(H14,0)+IFERROR(J14,0),0),IF(F14="Rented",IFERROR(IFERROR(H14,0)+IFERROR(N14,0),0),"")) | W14: =IF(F14="Own",IFERROR(IFERROR(K14,0)+IFERROR(L14,0)+IFERROR(M14,0)+IFERROR(N14,0)+IFERROR(O14,0)+IFERROR(P14,0)+IFERROR(Q14,0)+IFERROR(R14,0)+IFERROR(S14,0)+IFERROR(T14,0)+IFERROR(U14,0),0),IF(F14="Rented",0,"")) | X14: =IF(F14="Own",IFERROR(V14-W14,0),IF(F14="Rented",IFERROR(V14,0),"")) | AA14: =Settings!B41 -> Vehicle Maintenance
A15: 11 | V15: =IF(F15="Own",IFERROR(IFERROR(G15,0)+IFERROR(H15,0)+IFERROR(J15,0),0),IF(F15="Rented",IFERROR(IFERROR(H15,0)+IFERROR(N15,0),0),"")) | W15: =IF(F15="Own",IFERROR(IFERROR(K15,0)+IFERROR(L15,0)+IFERROR(M15,0)+IFERROR(N15,0)+IFERROR(O15,0)+IFERROR(P15,0)+IFERROR(Q15,0)+IFERROR(R15,0)+IFERROR(S15,0)+IFERROR(T15,0)+IFERROR(U15,0),0),IF(F15="Rented",0,"")) | X15: =IF(F15="Own",IFERROR(V15-W15,0),IF(F15="Rented",IFERROR(V15,0),"")) | AA15: =Settings!B42 -> Shop Rent
A16: 12 | V16: =IF(F16="Own",IFERROR(IFERROR(G16,0)+IFERROR(H16,0)+IFERROR(J16,0),0),IF(F16="Rented",IFERROR(IFERROR(H16,0)+IFERROR(N16,0),0),"")) | W16: =IF(F16="Own",IFERROR(IFERROR(K16,0)+IFERROR(L16,0)+IFERROR(M16,0)+IFERROR(N16,0)+IFERROR(O16,0)+IFERROR(P16,0)+IFERROR(Q16,0)+IFERROR(R16,0)+IFERROR(S16,0)+IFERROR(T16,0)+IFERROR(U16,0),0),IF(F16="Rented",0,"")) | X16: =IF(F16="Own",IFERROR(V16-W16,0),IF(F16="Rented",IFERROR(V16,0),"")) | AA16: =Settings!B43 -> Electricity & Bills
... A27: 23 | V27: =IF(F27="Own",IFERROR(IFERROR(G27,0)+IFERROR(H27,0)+IFERROR(J27,0),0),IF(F27="Rented",IFERROR(IFERROR(H27,0)+IFERROR(N27,0),0),"")) | W27: =IF(F27="Own",IFERROR(IFERROR(K27,0)+IFERROR(L27,0)+IFERROR(M27,0)+IFERROR(N27,0)+IFERROR(O27,0)+IFERROR(P27,0)+IFERROR(Q27,0)+IFERROR(R27,0)+IFERROR(S27,0)+IFERROR(T27,0)+IFERROR(U27,0),0),IF(F27="Rented",0,"")) | X27: =IF(F27="Own",IFERROR(V27-W27,0),IF(F27="Rented",IFERROR(V27,0),"")) | AA27: =Settings!B54 -> Misc 6
A28: 24 | V28: =IF(F28="Own",IFERROR(IFERROR(G28,0)+IFERROR(H28,0)+IFERROR(J28,0),0),IF(F28="Rented",IFERROR(IFERROR(H28,0)+IFERROR(N28,0),0),"")) | W28: =IF(F28="Own",IFERROR(IFERROR(K28,0)+IFERROR(L28,0)+IFERROR(M28,0)+IFERROR(N28,0)+IFERROR(O28,0)+IFERROR(P28,0)+IFERROR(Q28,0)+IFERROR(R28,0)+IFERROR(S28,0)+IFERROR(T28,0)+IFERROR(U28,0),0),IF(F28="Rented",0,"")) | X28: =IF(F28="Own",IFERROR(V28-W28,0),IF(F28="Rented",IFERROR(V28,0),""))
A29: 25 | V29: =IF(F29="Own",IFERROR(IFERROR(G29,0)+IFERROR(H29,0)+IFERROR(J29,0),0),IF(F29="Rented",IFERROR(IFERROR(H29,0)+IFERROR(N29,0),0),"")) | W29: =IF(F29="Own",IFERROR(IFERROR(K29,0)+IFERROR(L29,0)+IFERROR(M29,0)+IFERROR(N29,0)+IFERROR(O29,0)+IFERROR(P29,0)+IFERROR(Q29,0)+IFERROR(R29,0)+IFERROR(S29,0)+IFERROR(T29,0)+IFERROR(U29,0),0),IF(F29="Rented",0,"")) | X29: =IF(F29="Own",IFERROR(V29-W29,0),IF(F29="Rented",IFERROR(V29,0),""))
A30: 26 | V30: =IF(F30="Own",IFERROR(IFERROR(G30,0)+IFERROR(H30,0)+IFERROR(J30,0),0),IF(F30="Rented",IFERROR(IFERROR(H30,0)+IFERROR(N30,0),0),"")) | W30: =IF(F30="Own",IFERROR(IFERROR(K30,0)+IFERROR(L30,0)+IFERROR(M30,0)+IFERROR(N30,0)+IFERROR(O30,0)+IFERROR(P30,0)+IFERROR(Q30,0)+IFERROR(R30,0)+IFERROR(S30,0)+IFERROR(T30,0)+IFERROR(U30,0),0),IF(F30="Rented",0,"")) | X30: =IF(F30="Own",IFERROR(V30-W30,0),IF(F30="Rented",IFERROR(V30,0),""))
A31: 27 | V31: =IF(F31="Own",IFERROR(IFERROR(G31,0)+IFERROR(H31,0)+IFERROR(J31,0),0),IF(F31="Rented",IFERROR(IFERROR(H31,0)+IFERROR(N31,0),0),"")) | W31: =IF(F31="Own",IFERROR(IFERROR(K31,0)+IFERROR(L31,0)+IFERROR(M31,0)+IFERROR(N31,0)+IFERROR(O31,0)+IFERROR(P31,0)+IFERROR(Q31,0)+IFERROR(R31,0)+IFERROR(S31,0)+IFERROR(T31,0)+IFERROR(U31,0),0),IF(F31="Rented",0,"")) | X31: =IF(F31="Own",IFERROR(V31-W31,0),IF(F31="Rented",IFERROR(V31,0),""))
A32: 28 | V32: =IF(F32="Own",IFERROR(IFERROR(G32,0)+IFERROR(H32,0)+IFERROR(J32,0),0),IF(F32="Rented",IFERROR(IFERROR(H32,0)+IFERROR(N32,0),0),"")) | W32: =IF(F32="Own",IFERROR(IFERROR(K32,0)+IFERROR(L32,0)+IFERROR(M32,0)+IFERROR(N32,0)+IFERROR(O32,0)+IFERROR(P32,0)+IFERROR(Q32,0)+IFERROR(R32,0)+IFERROR(S32,0)+IFERROR(T32,0)+IFERROR(U32,0),0),IF(F32="Rented",0,"")) | X32: =IF(F32="Own",IFERROR(V32-W32,0),IF(F32="Rented",IFERROR(V32,0),""))
A33: 29 | V33: =IF(F33="Own",IFERROR(IFERROR(G33,0)+IFERROR(H33,0)+IFERROR(J33,0),0),IF(F33="Rented",IFERROR(IFERROR(H33,0)+IFERROR(N33,0),0),"")) | W33: =IF(F33="Own",IFERROR(IFERROR(K33,0)+IFERROR(L33,0)+IFERROR(M33,0)+IFERROR(N33,0)+IFERROR(O33,0)+IFERROR(P33,0)+IFERROR(Q33,0)+IFERROR(R33,0)+IFERROR(S33,0)+IFERROR(T33,0)+IFERROR(U33,0),0),IF(F33="Rented",0,"")) | X33: =IF(F33="Own",IFERROR(V33-W33,0),IF(F33="Rented",IFERROR(V33,0),""))
A34: 30 | V34: =IF(F34="Own",IFERROR(IFERROR(G34,0)+IFERROR(H34,0)+IFERROR(J34,0),0),IF(F34="Rented",IFERROR(IFERROR(H34,0)+IFERROR(N34,0),0),"")) | W34: =IF(F34="Own",IFERROR(IFERROR(K34,0)+IFERROR(L34,0)+IFERROR(M34,0)+IFERROR(N34,0)+IFERROR(O34,0)+IFERROR(P34,0)+IFERROR(Q34,0)+IFERROR(R34,0)+IFERROR(S34,0)+IFERROR(T34,0)+IFERROR(U34,0),0),IF(F34="Rented",0,"")) | X34: =IF(F34="Own",IFERROR(V34-W34,0),IF(F34="Rented",IFERROR(V34,0),""))
A35: 31 | V35: =IF(F35="Own",IFERROR(IFERROR(G35,0)+IFERROR(H35,0)+IFERROR(J35,0),0),IF(F35="Rented",IFERROR(IFERROR(H35,0)+IFERROR(N35,0),0),"")) | W35: =IF(F35="Own",IFERROR(IFERROR(K35,0)+IFERROR(L35,0)+IFERROR(M35,0)+IFERROR(N35,0)+IFERROR(O35,0)+IFERROR(P35,0)+IFERROR(Q35,0)+IFERROR(R35,0)+IFERROR(S35,0)+IFERROR(T35,0)+IFERROR(U35,0),0),IF(F35="Rented",0,"")) | X35: =IF(F35="Own",IFERROR(V35-W35,0),IF(F35="Rented",IFERROR(V35,0),""))
A36: 32 | V36: =IF(F36="Own",IFERROR(IFERROR(G36,0)+IFERROR(H36,0)+IFERROR(J36,0),0),IF(F36="Rented",IFERROR(IFERROR(H36,0)+IFERROR(N36,0),0),"")) | W36: =IF(F36="Own",IFERROR(IFERROR(K36,0)+IFERROR(L36,0)+IFERROR(M36,0)+IFERROR(N36,0)+IFERROR(O36,0)+IFERROR(P36,0)+IFERROR(Q36,0)+IFERROR(R36,0)+IFERROR(S36,0)+IFERROR(T36,0)+IFERROR(U36,0),0),IF(F36="Rented",0,"")) | X36: =IF(F36="Own",IFERROR(V36-W36,0),IF(F36="Rented",IFERROR(V36,0),""))
A37: 33 | V37: =IF(F37="Own",IFERROR(IFERROR(G37,0)+IFERROR(H37,0)+IFERROR(J37,0),0),IF(F37="Rented",IFERROR(IFERROR(H37,0)+IFERROR(N37,0),0),"")) | W37: =IF(F37="Own",IFERROR(IFERROR(K37,0)+IFERROR(L37,0)+IFERROR(M37,0)+IFERROR(N37,0)+IFERROR(O37,0)+IFERROR(P37,0)+IFERROR(Q37,0)+IFERROR(R37,0)+IFERROR(S37,0)+IFERROR(T37,0)+IFERROR(U37,0),0),IF(F37="Rented",0,"")) | X37: =IF(F37="Own",IFERROR(V37-W37,0),IF(F37="Rented",IFERROR(V37,0),""))
A38: 34 | V38: =IF(F38="Own",IFERROR(IFERROR(G38,0)+IFERROR(H38,0)+IFERROR(J38,0),0),IF(F38="Rented",IFERROR(IFERROR(H38,0)+IFERROR(N38,0),0),"")) | W38: =IF(F38="Own",IFERROR(IFERROR(K38,0)+IFERROR(L38,0)+IFERROR(M38,0)+IFERROR(N38,0)+IFERROR(O38,0)+IFERROR(P38,0)+IFERROR(Q38,0)+IFERROR(R38,0)+IFERROR(S38,0)+IFERROR(T38,0)+IFERROR(U38,0),0),IF(F38="Rented",0,"")) | X38: =IF(F38="Own",IFERROR(V38-W38,0),IF(F38="Rented",IFERROR(V38,0),""))
A39: 35 | V39: =IF(F39="Own",IFERROR(IFERROR(G39,0)+IFERROR(H39,0)+IFERROR(J39,0),0),IF(F39="Rented",IFERROR(IFERROR(H39,0)+IFERROR(N39,0),0),"")) | W39: =IF(F39="Own",IFERROR(IFERROR(K39,0)+IFERROR(L39,0)+IFERROR(M39,0)+IFERROR(N39,0)+IFERROR(O39,0)+IFERROR(P39,0)+IFERROR(Q39,0)+IFERROR(R39,0)+IFERROR(S39,0)+IFERROR(T39,0)+IFERROR(U39,0),0),IF(F39="Rented",0,"")) | X39: =IF(F39="Own",IFERROR(V39-W39,0),IF(F39="Rented",IFERROR(V39,0),""))
... A115: 111 | V115: =IF(F115="Own",IFERROR(IFERROR(G115,0)+IFERROR(H115,0)+IFERROR(J115,0),0),IF(F115="Rented",IFERROR(IFERROR(H115,0)+IFERROR(N115,0),0),"")) | W115: =IF(F115="Own",IFERROR(IFERROR(K115,0)+IFERROR(L115,0)+IFERROR(M115,0)+IFERROR(N115,0)+IFERROR(O115,0)+IFERROR(P115,0)+IFERROR(Q115,0)+IFERROR(R115,0)+IFERROR(S115,0)+IFERROR(T115,0)+IFERROR(U115,0),0),IF(F115="Rented",0,"")) | X115: =IF(F115="Own",IFERROR(V115-W115,0),IF(F115="Rented",IFERROR(V115,0),""))
A116: TRIP TOTALS | G116: =IFERROR(SUM(G5:G115),0) -> 0 | H116: =IFERROR(SUM(H5:H115),0) -> 0 | I116: =IFERROR(SUM(I5:I115),0) -> 0 | J116: =IFERROR(SUM(J5:J115),0) -> 0 | K116: =IFERROR(SUM(K5:K115),0) -> 0 | L116: =IFERROR(SUM(L5:L115),0) -> 0 | M116: =IFERROR(SUM(M5:M115),0) -> 0 | N116: =IFERROR(SUM(N5:N115),0) -> 0 | ... X116: =IFERROR(SUM(X5:X115),0) -> 0 | Y116: =COUNTA(C5:C115)&" trips" -> 0 trips | AA116: OVERHEAD TOTAL | AB116: =IFERROR(SUM(AB5:AB27),0) -> 0
A118: VEHICLE TYPE SUMMARY (auto-calculated from Type column F)
B119: Type | C119: Revenue ₹ | D119: Received ₹ | E119: Return/Adj ₹ | F119: Pending Freight ₹ | G119: Trip Expenses ₹ | H119: Trip Profit ₹ | I119: Trips
B120: OWN VEHICLES | C120: =IFERROR(SUMIF(F5:F115,"Own",G5:G115),0) -> 0 | D120: =IFERROR(SUMIF(F5:F115,"Own",H5:H115),0) -> 0 | E120: =IFERROR(SUMIF(F5:F115,"Own",J5:J115),0) -> 0 | F120: =IFERROR(SUMIF(F5:F115,"Own",I5:I115),0) -> 0 | G120: =IFERROR(SUMIF(F5:F115,"Own",W5:W115),0) -> 0 | H120: =IFERROR(SUMIF(F5:F115,"Own",X5:X115),0) -> 0 | I120: =IFERROR(COUNTIF(F5:F115,"Own"),0) -> 0
B121: RENTED VEHICLES | C121: =IFERROR(SUMIF(F5:F115,"Rented",G5:G115),0) -> 0 | D121: =IFERROR(SUMIF(F5:F115,"Rented",H5:H115),0) -> 0 | E121: =IFERROR(SUMIF(F5:F115,"Rented",J5:J115),0) -> 0 | F121: =IFERROR(SUMIF(F5:F115,"Rented",I5:I115),0) -> 0 | G121: =IFERROR(SUMIF(F5:F115,"Rented",W5:W115),0) -> 0 | H121: =IFERROR(SUMIF(F5:F115,"Rented",X5:X115),0) -> 0 | I121: =IFERROR(COUNTIF(F5:F115,"Rented"),0) -> 0
B122: TOTAL | C122: =C120+C121 -> 0 | D122: =D120+D121 -> 0 | E122: =E120+E121 -> 0 | F122: =F120+F121 -> 0 | G122: =G120+G121 -> 0 | H122: =H120+H121 -> 0 | I122: =I120+I121 -> 0
A124: MONTHLY P&L SUMMARY — MAY 2026
A125: Description | H125: Amount (₹) | I125: Note
A126: INCOME / REVENUE
A127: Revenue (To Pay) — total billed to customers | H127: =G116 -> 0 | I127: Gross billed for all trips
A128: Received (Paid) — cash actually collected | H128: =H116 -> 0 | I128: Cash received from customers
...

Sheet Jun 26
A2: ANCL LOGISTICS · MONTHLY TRIP & ACCOUNTS LOG · JUN 2026
A3: 🟩 Green = Income 🟥 Red = Expenses 🟦 Blue = Auto-calculated 🟨 Enter here | Pending Freight = manual entry only | O3: Own Vehicle: Trip Profit = (Rev+Recd+Adj) − (Bhatta+Hamali+…+Misc3) | Rented Vehicle: Trip Profit = Received + Attach Comm | AA3: FIXED / OVERHEAD EXPENSES (enter once per month)
A4: S.No | B4: Date | C4: TS # | D4: Vehicle No. | E4: Driver | F4: Type (Own/Rented) | G4: Revenue (To Pay ₹) | H4: Received (Paid ₹) | I4: Pending Freight ₹ | J4: Return / Adj ₹ | K4: Bhatta ₹ | L4: Hamali ₹ | M4: Diesel HBL ₹ | N4: Attach Comm ₹ | O4: Diesel MLP ₹ | P4: Tea / Snacks ₹ | Q4: Vehicle Maint ₹ | R4: Salary ₹ | S4: Misc 1 ₹ | T4: Misc 2 ₹ | U4: Misc 3 ₹ | V4: Trip Revenue (auto) ₹ | W4: Trip Expenses (auto) ₹ | X4: Trip Profit (auto) ₹ | Y4: Notes / Description | AA4: Overhead Category | AB4: Amount ₹ | AC4: Date | AD4: Description / Explanation
A5: 1 | V5: =IF(F5="Own",IFERROR(IFERROR(G5,0)+IFERROR(H5,0)+IFERROR(J5,0),0),IF(F5="Rented",IFERROR(IFERROR(H5,0)+IFERROR(N5,0),0),"")) | W5: =IF(F5="Own",IFERROR(IFERROR(K5,0)+IFERROR(L5,0)+IFERROR(M5,0)+IFERROR(N5,0)+IFERROR(O5,0)+IFERROR(P5,0)+IFERROR(Q5,0)+IFERROR(R5,0)+IFERROR(S5,0)+IFERROR(T5,0)+IFERROR(U5,0),0),IF(F5="Rented",0,"")) | X5: =IF(F5="Own",IFERROR(V5-W5,0),IF(F5="Rented",IFERROR(V5,0),"")) | AA5: =Settings!B32 -> Diesel MLP / Bulk
A6: 2 | V6: =IF(F6="Own",IFERROR(IFERROR(G6,0)+IFERROR(H6,0)+IFERROR(J6,0),0),IF(F6="Rented",IFERROR(IFERROR(H6,0)+IFERROR(N6,0),0),"")) | W6: =IF(F6="Own",IFERROR(IFERROR(K6,0)+IFERROR(L6,0)+IFERROR(M6,0)+IFERROR(N6,0)+IFERROR(O6,0)+IFERROR(P6,0)+IFERROR(Q6,0)+IFERROR(R6,0)+IFERROR(S6,0)+IFERROR(T6,0)+IFERROR(U6,0),0),IF(F6="Rented",0,"")) | X6: =IF(F6="Own",IFERROR(V6-W6,0),IF(F6="Rented",IFERROR(V6,0),"")) | AA6: =Settings!B33 -> Driver Salaries
A7: 3 | V7: =IF(F7="Own",IFERROR(IFERROR(G7,0)+IFERROR(H7,0)+IFERROR(J7,0),0),IF(F7="Rented",IFERROR(IFERROR(H7,0)+IFERROR(N7,0),0),"")) | W7: =IF(F7="Own",IFERROR(IFERROR(K7,0)+IFERROR(L7,0)+IFERROR(M7,0)+IFERROR(N7,0)+IFERROR(O7,0)+IFERROR(P7,0)+IFERROR(Q7,0)+IFERROR(R7,0)+IFERROR(S7,0)+IFERROR(T7,0)+IFERROR(U7,0),0),IF(F7="Rented",0,"")) | X7: =IF(F7="Own",IFERROR(V7-W7,0),IF(F7="Rented",IFERROR(V7,0),"")) | AA7: =Settings!B34 -> Vehicle EMI - 7195
A8: 4 | V8: =IF(F8="Own",IFERROR(IFERROR(G8,0)+IFERROR(H8,0)+IFERROR(J8,0),0),IF(F8="Rented",IFERROR(IFERROR(H8,0)+IFERROR(N8,0),0),"")) | W8: =IF(F8="Own",IFERROR(IFERROR(K8,0)+IFERROR(L8,0)+IFERROR(M8,0)+IFERROR(N8,0)+IFERROR(O8,0)+IFERROR(P8,0)+IFERROR(Q8,0)+IFERROR(R8,0)+IFERROR(S8,0)+IFERROR(T8,0)+IFERROR(U8,0),0),IF(F8="Rented",0,"")) | X8: =IF(F8="Own",IFERROR(V8-W8,0),IF(F8="Rented",IFERROR(V8,0),"")) | AA8: =Settings!B35 -> Vehicle EMI - 4608
A9: 5 | V9: =IF(F9="Own",IFERROR(IFERROR(G9,0)+IFERROR(H9,0)+IFERROR(J9,0),0),IF(F9="Rented",IFERROR(IFERROR(H9,0)+IFERROR(N9,0),0),"")) | W9: =IF(F9="Own",IFERROR(IFERROR(K9,0)+IFERROR(L9,0)+IFERROR(M9,0)+IFERROR(N9,0)+IFERROR(O9,0)+IFERROR(P9,0)+IFERROR(Q9,0)+IFERROR(R9,0)+IFERROR(S9,0)+IFERROR(T9,0)+IFERROR(U9,0),0),IF(F9="Rented",0,"")) | X9: =IF(F9="Own",IFERROR(V9-W9,0),IF(F9="Rented",IFERROR(V9,0),"")) | AA9: =Settings!B36 -> Vehicle EMI - 6421
A10: 6 | V10: =IF(F10="Own",IFERROR(IFERROR(G10,0)+IFERROR(H10,0)+IFERROR(J10,0),0),IF(F10="Rented",IFERROR(IFERROR(H10,0)+IFERROR(N10,0),0),"")) | W10: =IF(F10="Own",IFERROR(IFERROR(K10,0)+IFERROR(L10,0)+IFERROR(M10,0)+IFERROR(N10,0)+IFERROR(O10,0)+IFERROR(P10,0)+IFERROR(Q10,0)+IFERROR(R10,0)+IFERROR(S10,0)+IFERROR(T10,0)+IFERROR(U10,0),0),IF(F10="Rented",0,"")) | X10: =IF(F10="Own",IFERROR(V10-W10,0),IF(F10="Rented",IFERROR(V10,0),"")) | AA10: =Settings!B37 -> Vehicle EMI - 8660
A11: 7 | V11: =IF(F11="Own",IFERROR(IFERROR(G11,0)+IFERROR(H11,0)+IFERROR(J11,0),0),IF(F11="Rented",IFERROR(IFERROR(H11,0)+IFERROR(N11,0),0),"")) | W11: =IF(F11="Own",IFERROR(IFERROR(K11,0)+IFERROR(L11,0)+IFERROR(M11,0)+IFERROR(N11,0)+IFERROR(O11,0)+IFERROR(P11,0)+IFERROR(Q11,0)+IFERROR(R11,0)+IFERROR(S11,0)+IFERROR(T11,0)+IFERROR(U11,0),0),IF(F11="Rented",0,"")) | X11: =IF(F11="Own",IFERROR(V11-W11,0),IF(F11="Rented",IFERROR(V11,0),"")) | AA11: =Settings!B38 -> Vehicle EMI - 1288
A12: 8 | V12: =IF(F12="Own",IFERROR(IFERROR(G12,0)+IFERROR(H12,0)+IFERROR(J12,0),0),IF(F12="Rented",IFERROR(IFERROR(H12,0)+IFERROR(N12,0),0),"")) | W12: =IF(F12="Own",IFERROR(IFERROR(K12,0)+IFERROR(L12,0)+IFERROR(M12,0)+IFERROR(N12,0)+IFERROR(O12,0)+IFERROR(P12,0)+IFERROR(Q12,0)+IFERROR(R12,0)+IFERROR(S12,0)+IFERROR(T12,0)+IFERROR(U12,0),0),IF(F12="Rented",0,"")) | X12: =IF(F12="Own",IFERROR(V12-W12,0),IF(F12="Rented",IFERROR(V12,0),"")) | AA12: =Settings!B39 -> Vehicle EMI - 262
A13: 9 | V13: =IF(F13="Own",IFERROR(IFERROR(G13,0)+IFERROR(H13,0)+IFERROR(J13,0),0),IF(F13="Rented",IFERROR(IFERROR(H13,0)+IFERROR(N13,0),0),"")) | W13: =IF(F13="Own",IFERROR(IFERROR(K13,0)+IFERROR(L13,0)+IFERROR(M13,0)+IFERROR(N13,0)+IFERROR(O13,0)+IFERROR(P13,0)+IFERROR(Q13,0)+IFERROR(R13,0)+IFERROR(S13,0)+IFERROR(T13,0)+IFERROR(U13,0),0),IF(F13="Rented",0,"")) | X13: =IF(F13="Own",IFERROR(V13-W13,0),IF(F13="Rented",IFERROR(V13,0),"")) | AA13: =Settings!B40 -> Vehicle EMI - New Vehicle
A14: 10 | V14: =IF(F14="Own",IFERROR(IFERROR(G14,0)+IFERROR(H14,0)+IFERROR(J14,0),0),IF(F14="Rented",IFERROR(IFERROR(H14,0)+IFERROR(N14,0),0),"")) | W14: =IF(F14="Own",IFERROR(IFERROR(K14,0)+IFERROR(L14,0)+IFERROR(M14,0)+IFERROR(N14,0)+IFERROR(O14,0)+IFERROR(P14,0)+IFERROR(Q14,0)+IFERROR(R14,0)+IFERROR(S14,0)+IFERROR(T14,0)+IFERROR(U14,0),0),IF(F14="Rented",0,"")) | X14: =IF(F14="Own",IFERROR(V14-W14,0),IF(F14="Rented",IFERROR(V14,0),"")) | AA14: =Settings!B41 -> Vehicle Maintenance
A15: 11 | V15: =IF(F15="Own",IFERROR(IFERROR(G15,0)+IFERROR(H15,0)+IFERROR(J15,0),0),IF(F15="Rented",IFERROR(IFERROR(H15,0)+IFERROR(N15,0),0),"")) | W15: =IF(F15="Own",IFERROR(IFERROR(K15,0)+IFERROR(L15,0)+IFERROR(M15,0)+IFERROR(N15,0)+IFERROR(O15,0)+IFERROR(P15,0)+IFERROR(Q15,0)+IFERROR(R15,0)+IFERROR(S15,0)+IFERROR(T15,0)+IFERROR(U15,0),0),IF(F15="Rented",0,"")) | X15: =IF(F15="Own",IFERROR(V15-W15,0),IF(F15="Rented",IFERROR(V15,0),"")) | AA15: =Settings!B42 -> Shop Rent
A16: 12 | V16: =IF(F16="Own",IFERROR(IFERROR(G16,0)+IFERROR(H16,0)+IFERROR(J16,0),0),IF(F16="Rented",IFERROR(IFERROR(H16,0)+IFERROR(N16,0),0),"")) | W16: =IF(F16="Own",IFERROR(IFERROR(K16,0)+IFERROR(L16,0)+IFERROR(M16,0)+IFERROR(N16,0)+IFERROR(O16,0)+IFERROR(P16,0)+IFERROR(Q16,0)+IFERROR(R16,0)+IFERROR(S16,0)+IFERROR(T16,0)+IFERROR(U16,0),0),IF(F16="Rented",0,"")) | X16: =IF(F16="Own",IFERROR(V16-W16,0),IF(F16="Rented",IFERROR(V16,0),"")) | AA16: =Settings!B43 -> Electricity & Bills
... A27: 23 | V27: =IF(F27="Own",IFERROR(IFERROR(G27,0)+IFERROR(H27,0)+IFERROR(J27,0),0),IF(F27="Rented",IFERROR(IFERROR(H27,0)+IFERROR(N27,0),0),"")) | W27: =IF(F27="Own",IFERROR(IFERROR(K27,0)+IFERROR(L27,0)+IFERROR(M27,0)+IFERROR(N27,0)+IFERROR(O27,0)+IFERROR(P27,0)+IFERROR(Q27,0)+IFERROR(R27,0)+IFERROR(S27,0)+IFERROR(T27,0)+IFERROR(U27,0),0),IF(F27="Rented",0,"")) | X27: =IF(F27="Own",IFERROR(V27-W27,0),IF(F27="Rented",IFERROR(V27,0),"")) | AA27: =Settings!B54 -> Misc 6
A28: 24 | V28: =IF(F28="Own",IFERROR(IFERROR(G28,0)+IFERROR(H28,0)+IFERROR(J28,0),0),IF(F28="Rented",IFERROR(IFERROR(H28,0)+IFERROR(N28,0),0),"")) | W28: =IF(F28="Own",IFERROR(IFERROR(K28,0)+IFERROR(L28,0)+IFERROR(M28,0)+IFERROR(N28,0)+IFERROR(O28,0)+IFERROR(P28,0)+IFERROR(Q28,0)+IFERROR(R28,0)+IFERROR(S28,0)+IFERROR(T28,0)+IFERROR(U28,0),0),IF(F28="Rented",0,"")) | X28: =IF(F28="Own",IFERROR(V28-W28,0),IF(F28="Rented",IFERROR(V28,0),""))
A29: 25 | V29: =IF(F29="Own",IFERROR(IFERROR(G29,0)+IFERROR(H29,0)+IFERROR(J29,0),0),IF(F29="Rented",IFERROR(IFERROR(H29,0)+IFERROR(N29,0),0),"")) | W29: =IF(F29="Own",IFERROR(IFERROR(K29,0)+IFERROR(L29,0)+IFERROR(M29,0)+IFERROR(N29,0)+IFERROR(O29,0)+IFERROR(P29,0)+IFERROR(Q29,0)+IFERROR(R29,0)+IFERROR(S29,0)+IFERROR(T29,0)+IFERROR(U29,0),0),IF(F29="Rented",0,"")) | X29: =IF(F29="Own",IFERROR(V29-W29,0),IF(F29="Rented",IFERROR(V29,0),""))
A30: 26 | V30: =IF(F30="Own",IFERROR(IFERROR(G30,0)+IFERROR(H30,0)+IFERROR(J30,0),0),IF(F30="Rented",IFERROR(IFERROR(H30,0)+IFERROR(N30,0),0),"")) | W30: =IF(F30="Own",IFERROR(IFERROR(K30,0)+IFERROR(L30,0)+IFERROR(M30,0)+IFERROR(N30,0)+IFERROR(O30,0)+IFERROR(P30,0)+IFERROR(Q30,0)+IFERROR(R30,0)+IFERROR(S30,0)+IFERROR(T30,0)+IFERROR(U30,0),0),IF(F30="Rented",0,"")) | X30: =IF(F30="Own",IFERROR(V30-W30,0),IF(F30="Rented",IFERROR(V30,0),""))
A31: 27 | V31: =IF(F31="Own",IFERROR(IFERROR(G31,0)+IFERROR(H31,0)+IFERROR(J31,0),0),IF(F31="Rented",IFERROR(IFERROR(H31,0)+IFERROR(N31,0),0),"")) | W31: =IF(F31="Own",IFERROR(IFERROR(K31,0)+IFERROR(L31,0)+IFERROR(M31,0)+IFERROR(N31,0)+IFERROR(O31,0)+IFERROR(P31,0)+IFERROR(Q31,0)+IFERROR(R31,0)+IFERROR(S31,0)+IFERROR(T31,0)+IFERROR(U31,0),0),IF(F31="Rented",0,"")) | X31: =IF(F31="Own",IFERROR(V31-W31,0),IF(F31="Rented",IFERROR(V31,0),""))
A32: 28 | V32: =IF(F32="Own",IFERROR(IFERROR(G32,0)+IFERROR(H32,0)+IFERROR(J32,0),0),IF(F32="Rented",IFERROR(IFERROR(H32,0)+IFERROR(N32,0),0),"")) | W32: =IF(F32="Own",IFERROR(IFERROR(K32,0)+IFERROR(L32,0)+IFERROR(M32,0)+IFERROR(N32,0)+IFERROR(O32,0)+IFERROR(P32,0)+IFERROR(Q32,0)+IFERROR(R32,0)+IFERROR(S32,0)+IFERROR(T32,0)+IFERROR(U32,0),0),IF(F32="Rented",0,"")) | X32: =IF(F32="Own",IFERROR(V32-W32,0),IF(F32="Rented",IFERROR(V32,0),""))
A33: 29 | V33: =IF(F33="Own",IFERROR(IFERROR(G33,0)+IFERROR(H33,0)+IFERROR(J33,0),0),IF(F33="Rented",IFERROR(IFERROR(H33,0)+IFERROR(N33,0),0),"")) | W33: =IF(F33="Own",IFERROR(IFERROR(K33,0)+IFERROR(L33,0)+IFERROR(M33,0)+IFERROR(N33,0)+IFERROR(O33,0)+IFERROR(P33,0)+IFERROR(Q33,0)+IFERROR(R33,0)+IFERROR(S33,0)+IFERROR(T33,0)+IFERROR(U33,0),0),IF(F33="Rented",0,"")) | X33: =IF(F33="Own",IFERROR(V33-W33,0),IF(F33="Rented",IFERROR(V33,0),""))
A34: 30 | V34: =IF(F34="Own",IFERROR(IFERROR(G34,0)+IFERROR(H34,0)+IFERROR(J34,0),0),IF(F34="Rented",IFERROR(IFERROR(H34,0)+IFERROR(N34,0),0),"")) | W34: =IF(F34="Own",IFERROR(IFERROR(K34,0)+IFERROR(L34,0)+IFERROR(M34,0)+IFERROR(N34,0)+IFERROR(O34,0)+IFERROR(P34,0)+IFERROR(Q34,0)+IFERROR(R34,0)+IFERROR(S34,0)+IFERROR(T34,0)+IFERROR(U34,0),0),IF(F34="Rented",0,"")) | X34: =IF(F34="Own",IFERROR(V34-W34,0),IF(F34="Rented",IFERROR(V34,0),""))
A35: 31 | V35: =IF(F35="Own",IFERROR(IFERROR(G35,0)+IFERROR(H35,0)+IFERROR(J35,0),0),IF(F35="Rented",IFERROR(IFERROR(H35,0)+IFERROR(N35,0),0),"")) | W35: =IF(F35="Own",IFERROR(IFERROR(K35,0)+IFERROR(L35,0)+IFERROR(M35,0)+IFERROR(N35,0)+IFERROR(O35,0)+IFERROR(P35,0)+IFERROR(Q35,0)+IFERROR(R35,0)+IFERROR(S35,0)+IFERROR(T35,0)+IFERROR(U35,0),0),IF(F35="Rented",0,"")) | X35: =IF(F35="Own",IFERROR(V35-W35,0),IF(F35="Rented",IFERROR(V35,0),""))
A36: 32 | V36: =IF(F36="Own",IFERROR(IFERROR(G36,0)+IFERROR(H36,0)+IFERROR(J36,0),0),IF(F36="Rented",IFERROR(IFERROR(H36,0)+IFERROR(N36,0),0),"")) | W36: =IF(F36="Own",IFERROR(IFERROR(K36,0)+IFERROR(L36,0)+IFERROR(M36,0)+IFERROR(N36,0)+IFERROR(O36,0)+IFERROR(P36,0)+IFERROR(Q36,0)+IFERROR(R36,0)+IFERROR(S36,0)+IFERROR(T36,0)+IFERROR(U36,0),0),IF(F36="Rented",0,"")) | X36: =IF(F36="Own",IFERROR(V36-W36,0),IF(F36="Rented",IFERROR(V36,0),""))
A37: 33 | V37: =IF(F37="Own",IFERROR(IFERROR(G37,0)+IFERROR(H37,0)+IFERROR(J37,0),0),IF(F37="Rented",IFERROR(IFERROR(H37,0)+IFERROR(N37,0),0),"")) | W37: =IF(F37="Own",IFERROR(IFERROR(K37,0)+IFERROR(L37,0)+IFERROR(M37,0)+IFERROR(N37,0)+IFERROR(O37,0)+IFERROR(P37,0)+IFERROR(Q37,0)+IFERROR(R37,0)+IFERROR(S37,0)+IFERROR(T37,0)+IFERROR(U37,0),0),IF(F37="Rented",0,"")) | X37: =IF(F37="Own",IFERROR(V37-W37,0),IF(F37="Rented",IFERROR(V37,0),""))
A38: 34 | V38: =IF(F38="Own",IFERROR(IFERROR(G38,0)+IFERROR(H38,0)+IFERROR(J38,0),0),IF(F38="Rented",IFERROR(IFERROR(H38,0)+IFERROR(N38,0),0),"")) | W38: =IF(F38="Own",IFERROR(IFERROR(K38,0)+IFERROR(L38,0)+IFERROR(M38,0)+IFERROR(N38,0)+IFERROR(O38,0)+IFERROR(P38,0)+IFERROR(Q38,0)+IFERROR(R38,0)+IFERROR(S38,0)+IFERROR(T38,0)+IFERROR(U38,0),0),IF(F38="Rented",0,"")) | X38: =IF(F38="Own",IFERROR(V38-W38,0),IF(F38="Rented",IFERROR(V38,0),""))
A39: 35 | V39: =IF(F39="Own",IFERROR(IFERROR(G39,0)+IFERROR(H39,0)+IFERROR(J39,0),0),IF(F39="Rented",IFERROR(IFERROR(H39,0)+IFERROR(N39,0),0),"")) | W39: =IF(F39="Own",IFERROR(IFERROR(K39,0)+IFERROR(L39,0)+IFERROR(M39,0)+IFERROR(N39,0)+IFERROR(O39,0)+IFERROR(P39,0)+IFERROR(Q39,0)+IFERROR(R39,0)+IFERROR(S39,0)+IFERROR(T39,0)+IFERROR(U39,0),0),IF(F39="Rented",0,"")) | X39: =IF(F39="Own",IFERROR(V39-W39,0),IF(F39="Rented",IFERROR(V39,0),""))
... A115: 111 | V115: =IF(F115="Own",IFERROR(IFERROR(G115,0)+IFERROR(H115,0)+IFERROR(J115,0),0),IF(F115="Rented",IFERROR(IFERROR(H115,0)+IFERROR(N115,0),0),"")) | W115: =IF(F115="Own",IFERROR(IFERROR(K115,0)+IFERROR(L115,0)+IFERROR(M115,0)+IFERROR(N115,0)+IFERROR(O115,0)+IFERROR(P115,0)+IFERROR(Q115,0)+IFERROR(R115,0)+IFERROR(S115,0)+IFERROR(T115,0)+IFERROR(U115,0),0),IF(F115="Rented",0,"")) | X115: =IF(F115="Own",IFERROR(V115-W115,0),IF(F115="Rented",IFERROR(V115,0),""))
A116: TRIP TOTALS | G116: =IFERROR(SUM(G5:G115),0) -> 0 | H116: =IFERROR(SUM(H5:H115),0) -> 0 | I116: =IFERROR(SUM(I5:I115),0) -> 0 | J116: =IFERROR(SUM(J5:J115),0) -> 0 | K116: =IFERROR(SUM(K5:K115),0) -> 0 | L116: =IFERROR(SUM(L5:L115),0) -> 0 | M116: =IFERROR(SUM(M5:M115),0) -> 0 | N116: =IFERROR(SUM(N5:N115),0) -> 0 | ... X116: =IFERROR(SUM(X5:X115),0) -> 0 | Y116: =COUNTA(C5:C115)&" trips" -> 0 trips | AA116: OVERHEAD TOTAL | AB116: =IFERROR(SUM(AB5:AB27),0) -> 0
A118: VEHICLE TYPE SUMMARY (auto-calculated from Type column F)
B119: Type | C119: Revenue ₹ | D119: Received ₹ | E119: Return/Adj ₹ | F119: Pending Freight ₹ | G119: Trip Expenses ₹ | H119: Trip Profit ₹ | I119: Trips
B120: OWN VEHICLES | C120: =IFERROR(SUMIF(F5:F115,"Own",G5:G115),0) -> 0 | D120: =IFERROR(SUMIF(F5:F115,"Own",H5:H115),0) -> 0 | E120: =IFERROR(SUMIF(F5:F115,"Own",J5:J115),0) -> 0 | F120: =IFERROR(SUMIF(F5:F115,"Own",I5:I115),0) -> 0 | G120: =IFERROR(SUMIF(F5:F115,"Own",W5:W115),0) -> 0 | H120: =IFERROR(SUMIF(F5:F115,"Own",X5:X115),0) -> 0 | I120: =IFERROR(COUNTIF(F5:F115,"Own"),0) -> 0
B121: RENTED VEHICLES | C121: =IFERROR(SUMIF(F5:F115,"Rented",G5:G115),0) -> 0 | D121: =IFERROR(SUMIF(F5:F115,"Rented",H5:H115),0) -> 0 | E121: =IFERROR(SUMIF(F5:F115,"Rented",J5:J115),0) -> 0 | F121: =IFERROR(SUMIF(F5:F115,"Rented",I5:I115),0) -> 0 | G121: =IFERROR(SUMIF(F5:F115,"Rented",W5:W115),0) -> 0 | H121: =IFERROR(SUMIF(F5:F115,"Rented",X5:X115),0) -> 0 | I121: =IFERROR(COUNTIF(F5:F115,"Rented"),0) -> 0
B122: TOTAL | C122: =C120+C121 -> 0 | D122: =D120+D121 -> 0 | E122: =E120+E121 -> 0 | F122: =F120+F121 -> 0 | G122: =G120+G121 -> 0 | H122: =H120+H121 -> 0 | I122: =I120+I121 -> 0
A124: MONTHLY P&L SUMMARY — JUN 2026
